Workbook

Sheet BİLANÇO
A2: DUYAR POMPA VE HİDROFOR SİSTEMLERİ SAN. VE TİC. A.Ş.
A3: 30.06.2024 TARİHLİ AYRINTILI BİLANÇOSU
C5: Cari Dönem | F5: Cari Dönem
A6: 1A | B6: 1-DÖNEN VARLIKLAR | C6: =+C7+C13+C19+C28+C37+C45+C49+C52 -> 31888964 | D6: 3A | E6: 3-KISA VADELİ YABANCI KAYNAKLAR | F6: =SUM(F7+F17+F23+F30+F33+F36+F41+F47+F50) -> 29002519
A7: 10A | B7: A-Hazır Değerler | C7: =SUM(C8:C12) -> 4257507 | D7: 30A | E7: A-Mali Borçlar | F7: =SUM(F8:F16) -> 0
A8: 100A | B8: 1.Kasa | C8: =VLOOKUP(A8,CARİDÖNEM!A:F,6,FALSE)-VLOOKUP(A8,CARİDÖNEM!A:G,7,FALSE) -> 0 | D8: 300A | E8: 1. Banka Kredileri | F8: =VLOOKUP(D8,CARİDÖNEM!A:G,7,FALSE)-VLOOKUP(D8,CARİDÖNEM!A:F,6,FALSE) -> 0
A9: 101A | B9: 2.Alınan Çekler | C9: =VLOOKUP(A9,CARİDÖNEM!A:F,6,FALSE)-VLOOKUP(A9,CARİDÖNEM!A:G,7,FALSE) -> 3253028 | D9: 301A | E9: 2. Finansal Kiralama İşlemlerinden Doğan Borçlar | F9: =VLOOKUP(D9,CARİDÖNEM!A:G,7,FALSE)-VLOOKUP(D9,CARİDÖNEM!A:F,6,FALSE) -> 0
A10: 102A | B10: 3.Bankalar | C10: =VLOOKUP(A10,CARİDÖNEM!A:F,6,FALSE)-VLOOKUP(A10,CARİDÖNEM!A:G,7,FALSE) -> 1004479 | D10: 302A | E10: 3. Ertelenmiş Finansal Kiralama Borçlanma Maliyetleri (-) | F10: =VLOOKUP(D10,CARİDÖNEM!A:G,7,FALSE)-VLOOKUP(D10,CARİDÖNEM!A:F,6,FALSE) -> 0
A11: 103A | B11: 4. Verilen Çekler ve Ödeme Emir.(-) | C11: =VLOOKUP(A11,CARİDÖNEM!A:F,6,FALSE)-VLOOKUP(A11,CARİDÖNEM!A:G,7,FALSE) -> 0 | D11: 303A | E11: 4. Uzun Vadeli Kredilerin Anapara Taksitleri ve Faizleri | F11: =VLOOKUP(D11,CARİDÖNEM!A:G,7,FALSE)-VLOOKUP(D11,CARİDÖNEM!A:F,6,FALSE) -> 0
A12: 108A | B12: 5.Diğer Hazır Değerler | C12: =VLOOKUP(A12,CARİDÖNEM!A:F,6,FALSE)-VLOOKUP(A12,CARİDÖNEM!A:G,7,FALSE) -> 0 | D12: 304A | E12: 5. Tahvil, Anapara, Borç Taksit ve Faizleri | F12: =VLOOKUP(D12,CARİDÖNEM!A:G,7,FALSE)-VLOOKUP(D12,CARİDÖNEM!A:F,6,FALSE) -> 0
A13: 11A | B13: B-Menkul Kıymetler | C13: =SUM(C14:C18) -> 0 | D13: 305A | E13: 6. Çıkarılmış Bonolar ve Senetler | F13: =VLOOKUP(D13,CARİDÖNEM!A:G,7,FALSE)-VLOOKUP(D13,CARİDÖNEM!A:F,6,FALSE) -> 0
A14: 110A | B14: 1.Hisse Senetleri | C14: =VLOOKUP(A14,CARİDÖNEM!A:F,6,FALSE)-VLOOKUP(A14,CARİDÖNEM!A:G,7,FALSE) -> 0 | D14: 306A | E14: 7. Çıkarılmış Diğer Menkul Kıymetler | F14: =VLOOKUP(D14,CARİDÖNEM!A:G,7,FALSE)-VLOOKUP(D14,CARİDÖNEM!A:F,6,FALSE) -> 0
A15: 111A | B15: 2.Özel Kesim Tahvil, Senet ve Bonoları | C15: =VLOOKUP(A15,CARİDÖNEM!A:F,6,FALSE)-VLOOKUP(A15,CARİDÖNEM!A:G,7,FALSE) -> 0 | D15: 308A | E15: 8. Menkul Kıymetler İhraç Farkı (-) | F15: =VLOOKUP(D15,CARİDÖNEM!A:G,7,FALSE)-VLOOKUP(D15,CARİDÖNEM!A:F,6,FALSE) -> 0
A16: 112A | B16: 3.Kamu Kesimi Tahvil, Senet ve Bonoları | C16: =VLOOKUP(A16,CARİDÖNEM!A:F,6,FALSE)-VLOOKUP(A16,CARİDÖNEM!A:G,7,FALSE) -> 0 | D16: 309A | E16: 9. Diğer Mali Borçlar | F16: =VLOOKUP(D16,CARİDÖNEM!A:G,7,FALSE)-VLOOKUP(D16,CARİDÖNEM!A:F,6,FALSE) -> 0
A17: 118A | B17: 4.Diğer Menkul Kıymetler | C17: =VLOOKUP(A17,CARİDÖNEM!A:F,6,FALSE)-VLOOKUP(A17,CARİDÖNEM!A:G,7,FALSE) -> 0 | D17: 32A | E17: B-Ticari Borçlar | F17: =SUM(F18:F22) -> 16383030
A18: 119A | B18: 5.Menkul Kıymetler Değer Düşüklüğü Karşılığı (-) | C18: =VLOOKUP(A18,CARİDÖNEM!A:F,6,FALSE)-VLOOKUP(A18,CARİDÖNEM!A:G,7,FALSE) -> 0 | D18: 320A | E18: 1. Satıcılar | F18: =VLOOKUP(D18,CARİDÖNEM!A:G,7,FALSE)-VLOOKUP(D18,CARİDÖNEM!A:F,6,FALSE) -> 16383030
A19: 12A | B19: C-Ticari Alacaklar | C19: =SUM(C20:C27) -> 8406791.5 | D19: 321A | E19: 2. Borç Senetleri | F19: =VLOOKUP(D19,CARİDÖNEM!A:G,7,FALSE)-VLOOKUP(D19,CARİDÖNEM!A:F,6,FALSE) -> 0
A20: 120A | B20: 1. Alıcılar | C20: =VLOOKUP(A20,CARİDÖNEM!A:F,6,FALSE)-VLOOKUP(A20,CARİDÖNEM!A:G,7,FALSE) -> 8370652.4 | D20: 322A | E20: 3. Borç Senetleri Reeskontu (-) | F20: =VLOOKUP(D20,CARİDÖNEM!A:G,7,FALSE)-VLOOKUP(D20,CARİDÖNEM!A:F,6,FALSE) -> 0
A21: 121A | B21: 2. Alacak Senetleri | C21: =VLOOKUP(A21,CARİDÖNEM!A:F,6,FALSE)-VLOOKUP(A21,CARİDÖNEM!A:G,7,FALSE) -> 0 | D21: 326A | E21: 4. Alınan Depozito ve Teminatlar | F21: =VLOOKUP(D21,CARİDÖNEM!A:G,7,FALSE)-VLOOKUP(D21,CARİDÖNEM!A:F,6,FALSE) -> 0
A22: 122A | B22: 3. Alacak Senetleri Reeskontu (-) | C22: =VLOOKUP(A22,CARİDÖNEM!A:F,6,FALSE)-VLOOKUP(A22,CARİDÖNEM!A:G,7,FALSE) -> 0 | D22: 329A | E22: 5. Diğer Ticari Borçlar | F22: =VLOOKUP(D22,CARİDÖNEM!A:G,7,FALSE)-VLOOKUP(D22,CARİDÖNEM!A:F,6,FALSE) -> 0
A23: 124A | B23: 4. Kazanılmamış Finansal Kiralama Faiz Gelirleri (-) | C23: =VLOOKUP(A23,CARİDÖNEM!A:F,6,FALSE)-VLOOKUP(A23,CARİDÖNEM!A:G,7,FALSE) -> 0 | D23: 33A | E23: C-Diğer Borçlar | F23: =SUM(F24:F29) -> 6210109.7
A24: 126A | B24: 5. Verilen Depozito ve Teminatlar | C24: =VLOOKUP(A24,CARİDÖNEM!A:F,6,FALSE)-VLOOKUP(A24,CARİDÖNEM!A:G,7,FALSE) -> 36139.1 | D24: 331A | E24: 1. Ortaklara Borçlar | F24: =VLOOKUP(D24,CARİDÖNEM!A:G,7,FALSE)-VLOOKUP(D24,CARİDÖNEM!A:F,6,FALSE) -> 0
A25: 127A | B25: 6. Diğer Ticari Alacaklar | C25: =VLOOKUP(A25,CARİDÖNEM!A:F,6,FALSE)-VLOOKUP(A25,CARİDÖNEM!A:G,7,FALSE) -> 0 | D25: 332A | E25: 2. İştiraklere Borçlar | F25: =VLOOKUP(D25,CARİDÖNEM!A:G,7,FALSE)-VLOOKUP(D25,CARİDÖNEM!A:F,6,FALSE) -> 0
A26: 128A | B26: 7. Şüpheli Ticari Alacaklar | C26: =VLOOKUP(A26,CARİDÖNEM!A:F,6,FALSE)-VLOOKUP(A26,CARİDÖNEM!A:G,7,FALSE) -> 0 | D26: 333A | E26: 3. Bağlı Ortaklıklara Borçlar | F26: =VLOOKUP(D26,CARİDÖNEM!A:G,7,FALSE)-VLOOKUP(D26,CARİDÖNEM!A:F,6,FALSE) -> 0
A27: 129A | B27: 8. Şüpheli Ticari Alacaklar Karşılığı (-) | C27: =VLOOKUP(A27,CARİDÖNEM!A:F,6,FALSE)-VLOOKUP(A27,CARİDÖNEM!A:G,7,FALSE) -> 0 | D27: 335A | E27: 4. Personele Borçlar | F27: =VLOOKUP(D27,CARİDÖNEM!A:G,7,FALSE)-VLOOKUP(D27,CARİDÖNEM!A:F,6,FALSE) -> 1210109.7
A28: 13A | B28: D-Diğer Alacaklar | C28: =SUM(C29:C36) -> 12663.37 | D28: 336A | E28: 5. Diğer Çeşitli Borçlar | F28: =VLOOKUP(D28,CARİDÖNEM!A:G,7,FALSE)-VLOOKUP(D28,CARİDÖNEM!A:F,6,FALSE) -> 5000000
A29: 131A | B29: 1. Ortaklardan Alacaklar | C29: =VLOOKUP(A29,CARİDÖNEM!A:F,6,FALSE)-VLOOKUP(A29,CARİDÖNEM!A:G,7,FALSE) -> 0 | D29: 337A | E29: 6. Diğer Borç Senetleri Reeskontu (-) | F29: =VLOOKUP(D29,CARİDÖNEM!A:G,7,FALSE)-VLOOKUP(D29,CARİDÖNEM!A:F,6,FALSE) -> 0
A30: 132A | B30: 2. İştiraklerden Alacaklar | C30: =VLOOKUP(A30,CARİDÖNEM!A:F,6,FALSE)-VLOOKUP(A30,CARİDÖNEM!A:G,7,FALSE) -> 0 | D30: 34A | E30: D-Alınan Avanslar | F30: =SUM(F31:F32) -> 3596343.5
A31: 133A | B31: 3. Bağlı Ortaklıklardan Alacaklar | C31: =VLOOKUP(A31,CARİDÖNEM!A:F,6,FALSE)-VLOOKUP(A31,CARİDÖNEM!A:G,7,FALSE) -> 0 | D31: 340A | E31: 1. Alınan Sipariş Avansları | F31: =VLOOKUP(D31,CARİDÖNEM!A:G,7,FALSE)-VLOOKUP(D31,CARİDÖNEM!A:F,6,FALSE) -> 3596343.5
A32: 135A | B32: 4. Personelden Alacaklar | C32: =VLOOKUP(A32,CARİDÖNEM!A:F,6,FALSE)-VLOOKUP(A32,CARİDÖNEM!A:G,7,FALSE) -> 0 | D32: 349A | E32: 2. Alınan Diğer Avanslar | F32: =VLOOKUP(D32,CARİDÖNEM!A:G,7,FALSE)-VLOOKUP(D32,CARİDÖNEM!A:F,6,FALSE) -> 0
A33: 136A | B33: 5. Diğer Çeşitli Alacaklar | C33: =VLOOKUP(A33,CARİDÖNEM!A:F,6,FALSE)-VLOOKUP(A33,CARİDÖNEM!A:G,7,FALSE) -> 12663.37 | D33: 35A | E33: E-Yıllara Yaygın İnş. Ve On. Hak. | F33: =SUM(F34:F35) -> 0
A34: 137A | B34: 6. Diğer Alacak Senetleri Reeskontu (-) | C34: =VLOOKUP(A34,CARİDÖNEM!A:F,6,FALSE)-VLOOKUP(A34,CARİDÖNEM!A:G,7,FALSE) -> 0 | D34: 350A | E34: 1. Yıllara Yaygın İnşaat ve Onarım Hakediş Bedelleri | F34: =VLOOKUP(D34,CARİDÖNEM!A:G,7,FALSE)-VLOOKUP(D34,CARİDÖNEM!A:F,6,FALSE) -> 0
A35: 138A | B35: 7. Şüpheli Diğer Alacaklar | C35: =VLOOKUP(A35,CARİDÖNEM!A:F,6,FALSE)-VLOOKUP(A35,CARİDÖNEM!A:G,7,FALSE) -> 0 | D35: 358A | E35: 2. Yıllara Yaygın İnşaat Enflasyon Düzeltme Hesabı | F35: =VLOOKUP(D35,CARİDÖNEM!A:G,7,FALSE)-VLOOKUP(D35,CARİDÖNEM!A:F,6,FALSE) -> 0
A36: 139A | B36: 8. Şüpheli Diğer Alacaklar Karşılığı (-) | C36: =VLOOKUP(A36,CARİDÖNEM!A:F,6,FALSE)-VLOOKUP(A36,CARİDÖNEM!A:G,7,FALSE) -> 0 | D36: 36A | E36: F-Ödenecek Vergi ve Diğer Yükümlülükler | F36: =SUM(F37:F40) -> 1889336.3
A37: 15A | B37: E-Stoklar | C37: =SUM(C38:C44) -> 17248997 | D37: 360A | E37: 1. Ödenecek Vergi ve Fonları | F37: =VLOOKUP(D37,CARİDÖNEM!A:G,7,FALSE)-VLOOKUP(D37,CARİDÖNEM!A:F,6,FALSE) -> 817362.96
A38: 150A | B38: 1. İlk Madde ve Malzeme | C38: =VLOOKUP(A38,CARİDÖNEM!A:F,6,FALSE)-VLOOKUP(A38,CARİDÖNEM!A:G,7,FALSE) -> 8584765.7 | D38: 361A | E38: 2. Ödenecek Sosyal Güvenlik Kesintileri | F38: =VLOOKUP(D38,CARİDÖNEM!A:G,7,FALSE)-VLOOKUP(D38,CARİDÖNEM!A:F,6,FALSE) -> 1064225.3
A39: 151A | B39: 2. Yarı Mamüller-Üretim | C39: =VLOOKUP(A39,CARİDÖNEM!A:F,6,FALSE)-VLOOKUP(A39,CARİDÖNEM!A:G,7,FALSE) -> 6262019.5 | D39: 368A | E39: 3. Vadesi Geçmiş Ertelenmiş veya Taksitlendirilmiş Vergi ve Diğer Yükümlülükler | F39: =VLOOKUP(D39,CARİDÖNEM!A:G,7,FALSE)-VLOOKUP(D39,CARİDÖNEM!A:F,6,FALSE) -> 0
A40: 152A | B40: 3. Mamüller | C40: =VLOOKUP(A40,CARİDÖNEM!A:F,6,FALSE)-VLOOKUP(A40,CARİDÖNEM!A:G,7,FALSE) -> 1094817.9 | D40: 369A | E40: 4. Ödenecek Diğer Yükümlülükler | F40: =VLOOKUP(D40,CARİDÖNEM!A:G,7,FALSE)-VLOOKUP(D40,CARİDÖNEM!A:F,6,FALSE) -> 7748
A41: 153A | B41: 4. Ticari Mallar | C41: =VLOOKUP(A41,CARİDÖNEM!A:F,6,FALSE)-VLOOKUP(A41,CARİDÖNEM!A:G,7,FALSE) -> 831113.97 | D41: 37A | E41: G-Borç ve Gider Karşılıkları | F41: =SUM(F42:F46) -> 0
A42: 157A | B42: 5. Diğer Stoklar | C42: =VLOOKUP(A42,CARİDÖNEM!A:F,6,FALSE)-VLOOKUP(A42,CARİDÖNEM!A:G,7,FALSE) -> 0 | D42: 370A | E42: 1. Dönem Karı Vergi ve Diğer Yasal Yükümlülük Karşılıkları | F42: =VLOOKUP(D42,CARİDÖNEM!A:G,7,FALSE)-VLOOKUP(D42,CARİDÖNEM!A:F,6,FALSE) -> 0
...

Sheet GELİR TABLOSU
B2: DUYAR POMPA VE HİDROFOR SİSTEMLERİ SAN. VE TİC. A.Ş.
B3: 30.06.2024 TARİHLİ AYRINTILI GELİR TABLOSU
C5: Cari Dönem
B7: A-BRÜT SATIŞLAR | C7: =SUM(C8:C10) -> 58465508
A8: 600A | B8: 1-Yurt İçi Satışlar | C8: =VLOOKUP(A8,CARİDÖNEM!A:G,7,FALSE)+VLOOKUP(A8,CARİDÖNEM!A:F,6,FALSE) -> 48472645
A9: 601A | B9: 2-Yurt Dışı Satışlar | C9: =VLOOKUP(A9,CARİDÖNEM!A:G,7,FALSE)+VLOOKUP(A9,CARİDÖNEM!A:F,6,FALSE) -> 9543065.3
A10: 602A | B10: 3-Diğer Gelirler | C10: =VLOOKUP(A10,CARİDÖNEM!A:G,7,FALSE)+VLOOKUP(A10,CARİDÖNEM!A:F,6,FALSE) -> 449797.32
B11: B-SATIŞ İNDİRİMLERİ ( - ) | C11: =SUM(C12:C14) -> 374449.3
A12: 610A | B12: 1-Satıştan İadeler ( - ) | C12: =VLOOKUP(A12,CARİDÖNEM!A:G,7,FALSE)+VLOOKUP(A12,CARİDÖNEM!A:F,6,FALSE) -> 355451.5
A13: 611A | B13: 2-Satıştan İskontalar ( - ) | C13: =VLOOKUP(A13,CARİDÖNEM!A:G,7,FALSE)+VLOOKUP(A13,CARİDÖNEM!A:F,6,FALSE) -> 0
A14: 612A | B14: 3-Diğer İndirimler ( - ) | C14: =VLOOKUP(A14,CARİDÖNEM!A:G,7,FALSE)+VLOOKUP(A14,CARİDÖNEM!A:F,6,FALSE) -> 18997.8
B15: C-NET SATIŞLAR | C15: =C7-C11 -> 58091058
B16: D-SATIŞLARIN MALİYETİ ( - ) | C16: =SUM(C17:C20) -> 46047328
A17: 620A | B17: 1-Satılan Mamüller Maliyeti ( - ) | C17: =VLOOKUP(A17,CARİDÖNEM!A:G,7,FALSE)+VLOOKUP(A17,CARİDÖNEM!A:F,6,FALSE) -> 40699685
A18: 621A | B18: 2-Satılan Ticari Mallar Maliyeti ( - ) | C18: =VLOOKUP(A18,CARİDÖNEM!A:G,7,FALSE)+VLOOKUP(A18,CARİDÖNEM!A:F,6,FALSE) -> 4769332
A19: 622A | B19: 3-Satılan Hizmet Maliyeti ( - ) | C19: =VLOOKUP(A19,CARİDÖNEM!A:G,7,FALSE)+VLOOKUP(A19,CARİDÖNEM!A:F,6,FALSE) -> 0
A20: 623A | B20: 4-Diğer Satışların Maliyeti ( - ) | C20: =VLOOKUP(A20,CARİDÖNEM!A:G,7,FALSE)+VLOOKUP(A20,CARİDÖNEM!A:F,6,FALSE) -> 578310.33
B21: BRÜT SATIŞ KARI VEYA ZARARI | C21: =(C7-C11)-C16 -> 12043731
B22: E-FAALİYET GİDERLERİ | C22: =SUM(C23:C25) -> 12506569
A23: 630A | B23: 1-Araştırma ve Geliştirme Giderleri ( - ) | C23: =VLOOKUP(A23,CARİDÖNEM!A:G,7,FALSE)+VLOOKUP(A23,CARİDÖNEM!A:F,6,FALSE) -> 2017980.9
A24: 631A | B24: 2-Pazarlama, Satış ve Dağıtım Giderleri (-) | C24: =VLOOKUP(A24,CARİDÖNEM!A:G,7,FALSE)+VLOOKUP(A24,CARİDÖNEM!A:F,6,FALSE) -> 4115122.9
A25: 632A | B25: 3-Genel Yönetim Giderleri ( - ) | C25: =VLOOKUP(A25,CARİDÖNEM!A:G,7,FALSE)+VLOOKUP(A25,CARİDÖNEM!A:F,6,FALSE) -> 6373464.7
B26: FAALİYET KARI VEYA ZARARI | C26: =SUM(C21,-C22) -> -462838
B27: F-DİĞER FAALİYETLERDEN OLAĞAN GELİR VE KARLAR | C27: =SUM(C28:C37) -> 848831.63
A28: 640A | B28: 1-İştiraklerden Temettü Gelirleri | C28: =VLOOKUP(A28,CARİDÖNEM!A:G,7,FALSE)+VLOOKUP(A28,CARİDÖNEM!A:F,6,FALSE) -> 0
A29: 641A | B29: 2-Bağlı Ortaklıklardan Temettü Gelirleri | C29: =VLOOKUP(A29,CARİDÖNEM!A:G,7,FALSE)+VLOOKUP(A29,CARİDÖNEM!A:F,6,FALSE) -> 0
A30: 642A | B30: 3-Faiz Gelirleri | C30: =VLOOKUP(A30,CARİDÖNEM!A:G,7,FALSE)+VLOOKUP(A30,CARİDÖNEM!A:F,6,FALSE) -> 0
A31: 643A | B31: 4-Komisyon Gelirleri | C31: =VLOOKUP(A31,CARİDÖNEM!A:G,7,FALSE)+VLOOKUP(A31,CARİDÖNEM!A:F,6,FALSE) -> 0
A32: 644A | B32: 5-Konusu Kalmayan Karşılıklar | C32: =VLOOKUP(A32,CARİDÖNEM!A:G,7,FALSE)+VLOOKUP(A32,CARİDÖNEM!A:F,6,FALSE) -> 0
A33: 645A | B33: 6-Menkul Kıymet Satış Karları | C33: =VLOOKUP(A33,CARİDÖNEM!A:G,7,FALSE)+VLOOKUP(A33,CARİDÖNEM!A:F,6,FALSE) -> 0
A34: 646A | B34: 7-Kambiyo Karları | C34: =VLOOKUP(A34,CARİDÖNEM!A:G,7,FALSE)+VLOOKUP(A34,CARİDÖNEM!A:F,6,FALSE) -> 337735.13
A35: 647A | B35: 8-Reeskont Faiz Gelirleri | C35: =VLOOKUP(A35,CARİDÖNEM!A:G,7,FALSE)+VLOOKUP(A35,CARİDÖNEM!A:F,6,FALSE) -> 0
A36: 648A | B36: 9-Enflasyon Düzeltmesi Karları | C36: =VLOOKUP(A36,CARİDÖNEM!A:G,7,FALSE)+VLOOKUP(A36,CARİDÖNEM!A:F,6,FALSE) -> 0
A37: 649A | B37: 10-Diğer Olağan Gelir ve Karlar | C37: =VLOOKUP(A37,CARİDÖNEM!A:G,7,FALSE)+VLOOKUP(A37,CARİDÖNEM!A:F,6,FALSE) -> 511096.5
B38: G-DİĞER FAAL. OLAĞAN GİDER VE ZARARLAR(-) | C38: =SUM(C39:C45) -> 1435160.8
A39: 653A | B39: 1-Komisyon Giderleri ( - ) | C39: =VLOOKUP(A39,CARİDÖNEM!A:G,7,FALSE)+VLOOKUP(A39,CARİDÖNEM!A:F,6,FALSE) -> 570440.12
A40: 654A | B40: 2-Karşılık Giderleri ( - ) | C40: =VLOOKUP(A40,CARİDÖNEM!A:G,7,FALSE)+VLOOKUP(A40,CARİDÖNEM!A:F,6,FALSE) -> 0
A41: 655A | B41: 3-Menkul Kıymet Satış Zararları ( - ) | C41: =VLOOKUP(A41,CARİDÖNEM!A:G,7,FALSE)+VLOOKUP(A41,CARİDÖNEM!A:F,6,FALSE) -> 0
A42: 656A | B42: 4-Kambiyo Zararları ( - ) | C42: =VLOOKUP(A42,CARİDÖNEM!A:G,7,FALSE)+VLOOKUP(A42,CARİDÖNEM!A:F,6,FALSE) -> 797940.23
A43: 657A | B43: 5-Reeskont Faiz Giderleri ( - ) | C43: =VLOOKUP(A43,CARİDÖNEM!A:G,7,FALSE)+VLOOKUP(A43,CARİDÖNEM!A:F,6,FALSE) -> 0
...

Sheet CARİDÖNEM
A1: =CONCATENATE(B1,"A") -> G E N E L M İ Z A NA | B1: G E N E L M İ Z A N
A2: =CONCATENATE(B2,"A") -> Duyar Pompa ve Hidrofor Sistemleri San. ve Tic.A.Ş İşyeri Kod :A | B2: Duyar Pompa ve Hidrofor Sistemleri San. ve Tic.A.Ş İşyeri Kod :
A3: =CONCATENATE(B3,"A") -> A
A4: =CONCATENATE(B4,"A") -> 45523,6597222222A | B4: 45523.66
A5: =CONCATENATE(B5,"A") -> İlgili Tarih: 01/01/2024 - 30/06/2024A | B5: İlgili Tarih: 01/01/2024 - 30/06/2024
A6: =CONCATENATE(B6,"A") -> Sayfa No : 1A | B6: Sayfa No : 1
A7: =CONCATENATE(B7,"A") -> A
A8: =CONCATENATE(B8,"A") -> A
A9: =CONCATENATE(B9,"A") -> A
A10: =CONCATENATE(B10,"A") -> A
A11: =CONCATENATE(B11,"A") -> A
A12: =CONCATENATE(B12,"A") -> A
A13: =CONCATENATE(B13,"A") -> A
A14: =CONCATENATE(B14,"A") -> A
A15: =CONCATENATE(B15,"A") -> A | D15: T O P L A M | E15: T O P L A M | F15: B A K İ Y E | G15: B A K İ Y E
A16: =CONCATENATE(B16,"A") -> Hesap KoduA | B16: Hesap Kodu | C16: Hesap Adı | D16: B O R Ç | E16: A L A C A K | F16: B O R Ç | G16: A L A C A K
A17: =CONCATENATE(B17,"A") -> -------------------------A | B17: ------------------------- | C17: ----------------------------------- | D17: ------------------ | E17: ------------------ | F17: ------------------- | G17: -------------------
A18: =CONCATENATE(B18,"A") -> 1A | B18: 1 | C18: DÖNEN VARLIKLAR | D18: 0 | E18: 0 | F18: 0 | G18: 0
A19: =CONCATENATE(B19,"A") -> 100A | B19: 100 | C19: KASA HESABI | D19: 0 | E19: 0 | F19: 0 | G19: 0
A20: =CONCATENATE(B20,"A") -> 101A | B20: 101 | C20: ALINAN ÇEKLER | D20: 46339433 | E20: 43086405 | F20: 3253028 | G20: 0
A21: =CONCATENATE(B21,"A") -> 102A | B21: 102 | C21: BANKALAR | D21: 50247000 | E21: 49242521 | F21: 1004479 | G21: 0
A22: =CONCATENATE(B22,"A") -> 103A | B22: 103 | C22: VERİLEN ÇEKLER VE ÖDEME EMİRLERİ (- | D22: 0 | E22: 0 | F22: 0 | G22: 0
A23: =CONCATENATE(B23,"A") -> 108A | B23: 108 | C23: DİĞER HAZIR DEĞERLER | D23: 0 | E23: 0 | F23: 0 | G23: 0
A24: =CONCATENATE(B24,"A") -> 110A | B24: 110 | C24: HİSSE SENETLERİ | D24: 0 | E24: 0 | F24: 0 | G24: 0
A25: =CONCATENATE(B25,"A") -> 111A | B25: 111 | C25: ÖZEL KESİM TAHVİL SENET VE BONOLARI | D25: 0 | E25: 0 | F25: 0 | G25: 0
A26: =CONCATENATE(B26,"A") -> 112A | B26: 112 | C26: KAMU KESİMİ TAHVİL SENET VE BONOLAR | D26: 0 | E26: 0 | F26: 0 | G26: 0
A27: =CONCATENATE(B27,"A") -> 120A | B27: 120 | C27: ALICILAR | D27: 79069144 | E27: 70698491 | F27: 8370652.4 | G27: 0
A28: =CONCATENATE(B28,"A") -> 121A | B28: 121 | C28: ALACAK SENETLERİ | D28: 5140258.2 | E28: 5140258.2 | F28: 0 | G28: 0
A29: =CONCATENATE(B29,"A") -> 122A | B29: 122 | C29: ALACAK SENETLERİ REESKONTU (-) | D29: 0 | E29: 0 | F29: 0 | G29: 0
... A281: =CONCATENATE(B281,"A") -> 909A | B281: 909 | C281: UYUMSOFT DÜZELTME HESAPALRI | D281: 0 | E281: 0 | F281: 0 | G281: 0
A282: =CONCATENATE(B282,"A") -> T O P L A M :A | B282: T O P L A M : | D282: 5.9706412e+08 | E282: 5.9706412e+08 | F282: 1.6941645e+08 | G282: 1.6941645e+08
A283: =CONCATENATE(B283,"A") -> A
A284: =CONCATENATE(B284,"A") -> A
A285: =CONCATENATE(B285,"A") -> A
A286: =CONCATENATE(B286,"A") -> A
A287: =CONCATENATE(B287,"A") -> A
A288: =CONCATENATE(B288,"A") -> A
A289: =CONCATENATE(B289,"A") -> A
A290: =CONCATENATE(B290,"A") -> A
A291: =CONCATENATE(B291,"A") -> A
...

Sheet DETAY MİZAN
A1: G E N E L M İ Z A N
A2: DUYAR POMPA VE HİDROFOR SİSTEMLERİ SAN. VE TİC. A.Ş.
A3: İlgili Tarih: 01/01/2024-30/06/2024
C5: T O P L A M | D5: T O P L A M | E5: B A K İ Y E | F5: B A K İ Y E
A6: Hesap Kodu | B6: Hesap Adı | C6: B O R Ç | D6: A L A C A K | E6: B O R Ç | F6: A L A C A K
A7: ------------------------- | B7: ----------------------------------- | C7: ------------------ | D7: ------------------ | E7: ------------------- | F7: -------------------
A8: 101 | B8: ALINAN ÇEKLER | C8: 46339433 | D8: 43086405 | E8: 3253028 | F8: 0
A9: 101-01 | B9: PORTFÖYDEKİ ÇEKLER | C9: 40616319 | D9: 38893273 | E9: 1723046 | F9: 0
A10: 101-01-01 | B10: CÜZDANDAKİ ÇEKLER-TL | C10: 40616319 | D10: 38893273 | E10: 1723046 | F10: 0
A11: 101-02 | B11: TAHSİLE VERİLEN ÇEKLER | C11: 5723113.5 | D11: 4193131.5 | E11: 1529982 | F11: 0
A12: 101-02-01 | B12: TAHSİLE VERİLEN ÇEKLER-TL | C12: 5723113.5 | D12: 4193131.5 | E12: 1529982 | F12: 0
A13: 102 | B13: BANKALAR | C13: 50247000 | D13: 49242521 | E13: 1004479 | F13: 0
A14: 102-01 | B14: VADESİZ MEVDUATLAR | C14: 50247000 | D14: 49242521 | E14: 1004479 | F14: 0
A15: 102-01-01 | B15: VADESİZ MEVDUATLAR-TL | C15: 38030565 | D15: 37174244 | E15: 856320.53 | F15: 0
A16: 102-01-02 | B16: VADESİZ MEVDUATLAR-USD | C16: 5809283.9 | D16: 5662724.4 | E16: 146559.47 | F16: 0
A17: 102-01-03 | B17: VADESİZ MEVDUATLAR-EUR | C17: 6407151.6 | D17: 6405552.6 | E17: 1599.04 | F17: 0
A18: 120 | B18: ALICILAR | C18: 79069144 | D18: 70698491 | E18: 8370652.4 | F18: 0
A19: 120-01 | B19: YURTİÇİ ALICILAR | C19: 65118899 | D19: 61485743 | E19: 3633155.2 | F19: 0
A20: 120-01-01 | B20: YURTİÇİ ALICILAR-GRUP İÇİ | C20: 360296.8 | D20: 283109.89 | E20: 77186.91 | F20: 0
A21: 120-01-01-01 | B21: YURTİÇİ ALICILAR-GRUP İÇİ TL | C21: 360296.8 | D21: 283109.89 | E21: 77186.91 | F21: 0
A22: 120-01-02 | B22: YURTİÇİ ALICILAR-GRUP DIŞI | C22: 64758602 | D22: 61202634 | E22: 3555968.3 | F22: 0
A23: 120-01-02-01 | B23: YURTİÇİ ALICILAR-GRUP DIŞI TL | C23: 64758602 | D23: 61202634 | E23: 3555968.3 | F23: 0
A24: 120-02 | B24: YURTDIŞI ALICILAR | C24: 13950245 | D24: 9212747.6 | E24: 4737497.2 | F24: 0
A25: 120-02-01 | B25: YURTDIŞI ALICILAR-GRUP İÇİ | C25: 2662241.3 | D25: 744981.03 | E25: 1917260.3 | F25: 0
A26: 120-02-01-02 | B26: YURTDIŞI ALICILAR-GRUP İÇİ USD | C26: 2606578.2 | D26: 689317.86 | E26: 1917260.3 | F26: 0
A27: 120-02-01-03 | B27: YURTDIŞI ALICILAR-GRUP İÇİ EUR | C27: 55663.17 | D27: 55663.17 | E27: 0 | F27: 0
A28: 120-02-02 | B28: YURTDIŞI ALICILAR-GRUP DIŞI | C28: 11288003 | D28: 8467766.6 | E28: 2820236.9 | F28: 0
A29: 120-02-02-01 | B29: YURTDIŞI ALICILAR-GRUP DIŞI TL | C29: 2004504.2 | D29: 1513304.2 | E29: 491200 | F29: 0
A30: 120-02-02-02 | B30: YURTDIŞI ALICILAR-GRUP DIŞI USD | C30: 4148853.4 | D30: 1819816.5 | E30: 2329036.9 | F30: 0
A31: 120-02-02-03 | B31: YURTDIŞI ALICILAR-GRUP DIŞI EUR | C31: 5134645.9 | D31: 5134645.9 | E31: 0 | F31: 0
A32: 121 | B32: ALACAK SENETLERİ | C32: 5140258.2 | D32: 5140258.2 | E32: 0 | F32: 0
A33: 121-01 | B33: PORTFÖYDEKİ SENETLER | C33: 2206296.6 | D33: 2206296.6 | E33: 0 | F33: 0
A34: 121-01-01 | B34: CÜZDANDAKİ SENETLER TL | C34: 2206296.6 | D34: 2206296.6 | E34: 0 | F34: 0
A35: 121-02 | B35: TAHSİLE VERİLEN SENETLER | C35: 2933961.6 | D35: 2933961.6 | E35: 0 | F35: 0
A36: 121-02-01 | B36: TAHSİLE VERİLEN SENETLER TL | C36: 2933961.6 | D36: 2933961.6 | E36: 0 | F36: 0
A37: 126 | B37: VERİLEN DEPOZİTO VE TEMİNATLAR | C37: 36139.1 | D37: 0 | E37: 36139.1 | F37: 0
A38: 126-01 | B38: VERİLEN DEPOZİTO VE TEMİNATLAR | C38: 36139.1 | D38: 0 | E38: 36139.1 | F38: 0
A39: 126-01-04 | B39: ELEKTRİK DEPOZİTOSU | C39: 36139.1 | D39: 0 | E39: 36139.1 | F39: 0
A40: 136 | B40: DİĞER ÇEŞİTLİ ALACAKLAR | C40: 12663.37 | D40: 0 | E40: 12663.37 | F40: 0
A41: 136-01 | B41: DİĞER ÇEŞİTLİ ALACAKLAR | C41: 12663.37 | D41: 0 | E41: 12663.37 | F41: 0
...

Sheet 780HESAP
A1: Muhasebe Hareket Bilgileri (mhy03)
A3: Fiş Tarihi | B3: Fiş No | C3: Hesap Kodu | D3: Hesap Adı | E3: Kar Merkezi Kodu | F3: Kaynak Yeri | G3: Açıklama | H3: Borç Tutarı | I3: Alacak Tutarı | J3: Bakiye | K3: B/A | L3: Özel Kod-1 | M3: Özel Kod-2 | N3: Döviz | O3: Döviz Kuru | P3: Döviz Borç | Q3: Döviz Alacak | R3: Döviz Bakiye | S3: Birleştirilmiş Fiş No | T3: Madde No | U3: Gelir/Gider Kodu | V3: Analiz Kodu | W3: Proje Kodu | X3: Proje Tipi | Y3: İşyeri Kodu
A4: 45292 | G4: Önceden Devir | H4: 0 | I4: 0 | J4: 0 | O4: 0 | P4: 0 | Q4: 0 | R4: 0 | T4: 0
A5: 45293 | B5: 0102-00010 | C5: 780-01-03 | D5: BANKA MASRAFLARI | E5: 50-01-01 | F5: Banka | G5: EFT MASRAFI | H5: 438.74 | I5: 0 | J5: 438.74 | K5: B | O5: 0 | P5: 0 | Q5: 0 | R5: 0 | S5: 0102-00009 | T5: 23 | U5: 99-08 | V5: Banka-015
A6: 45295 | B6: 0104-00008 | C6: 780-01-03 | D6: BANKA MASRAFLARI | E6: 50-01-01 | F6: Banka | G6: BANKA EFT MASRAFI | H6: 0.26 | I6: 0 | J6: 439 | K6: B | O6: 0 | P6: 0 | Q6: 0 | R6: 0 | S6: 0104-00005 | T6: 81 | U6: 99-08 | V6: Banka-015
A7: 45300 | B7: 0109-00016 | C7: 780-01-03 | D7: BANKA MASRAFLARI | F7: Banka | G7: MUHABİR MASRAF BEDELİ | H7: 359.19 | I7: 0 | J7: 798.19 | K7: B | N7: usd | O7: 29.9327 | P7: 12 | Q7: 0 | R7: 12 | S7: 0109-00004 | T7: 190 | U7: 99-08 | V7: Banka-015
A8: 45310 | B8: 0119-00006 | C8: 780-01-03 | D8: BANKA MASRAFLARI | F8: Banka | G8: ZİRAAT BANKA MASRAFI | H8: 0.26 | I8: 0 | J8: 798.45 | K8: B | O8: 0 | P8: 0 | Q8: 0 | R8: 12 | S8: 0119-00005 | T8: 380 | V8: Banka-015
A9: 45310 | B9: 0119-00006 | C9: 780-01-03 | D9: BANKA MASRAFLARI | F9: Banka | G9: ZİRAAT BANKA MASRAFI | H9: 0.26 | I9: 0 | J9: 798.71 | K9: B | O9: 0 | P9: 0 | Q9: 0 | R9: 12 | S9: 0119-00005 | T9: 380 | V9: Banka-015
A10: 45315 | B10: 0124-00028 | C10: 780-01-03 | D10: BANKA MASRAFLARI | E10: 50-01-01 | F10: Banka | G10: ALİ KAAN ESMER İŞ AVANS ÖDEMESİ | H10: 394.14 | I10: 0 | J10: 1192.85 | K10: B | N10: USD | O10: 30.3184 | P10: 13 | Q10: 0 | R10: 25 | S10: 0124-00010 | T10: 487 | U10: 99-08 | V10: Banka-015
A11: 45317 | B11: 0126-00012 | C11: 780-01-03 | D11: BANKA MASRAFLARI | E11: 50-01-01 | F11: Banka | G11: ZİRAAT BANK EFT MASRAFI | H11: 0.26 | I11: 0 | J11: 1193.11 | K11: B | O11: 0 | P11: 0 | Q11: 0 | R11: 25 | S11: 0126-00008 | T11: 524 | U11: 99-08 | V11: Banka-015
A12: 45317 | B12: 0126-00012 | C12: 780-01-03 | D12: BANKA MASRAFLARI | E12: 50-01-01 | F12: Banka | G12: ZİRAAT BANK EFT MASRAFI | H12: 1.14 | I12: 0 | J12: 1194.25 | K12: B | O12: 0 | P12: 0 | Q12: 0 | R12: 25 | S12: 0126-00008 | T12: 524 | U12: 99-08 | V12: Banka-015
A13: 45320 | B13: 0129-00006 | C13: 780-01-03 | D13: BANKA MASRAFLARI | F13: Banka | G13: KOMİSYON TAKSİT ÖDEMESİ | H13: 590.62 | I13: 0 | J13: 1784.87 | K13: B | O13: 0 | P13: 0 | Q13: 0 | R13: 25 | S13: 0129-00001 | T13: 542 | V13: Banka-002
A14: 45321 | B14: 0130-00023 | C14: 780-01-03 | D14: BANKA MASRAFLARI | E14: 50-01-01 | F14: Banka | G14: ZİRAAT BANK EFT MASRAFI | H14: 30.88 | I14: 0 | J14: 1815.75 | K14: B | O14: 0 | P14: 0 | Q14: 0 | R14: 25 | S14: 0130-00023 | T14: 583 | U14: 99-08 | V14: Banka-015
A15: 45321 | B15: 0130-00023 | C15: 780-01-03 | D15: BANKA MASRAFLARI | E15: 50-01-01 | F15: Banka | G15: ZİRAAT BANK EFT MASRAFI | H15: 30.88 | I15: 0 | J15: 1846.63 | K15: B | O15: 0 | P15: 0 | Q15: 0 | R15: 25 | S15: 0130-00023 | T15: 583 | U15: 99-08 | V15: Banka-015
A16: 45321 | B16: 0130-00023 | C16: 780-01-03 | D16: BANKA MASRAFLARI | E16: 50-01-01 | F16: Banka | G16: ZİRAAT BANK EFT MASRAFI | H16: 30.88 | I16: 0 | J16: 1877.51 | K16: B | O16: 0 | P16: 0 | Q16: 0 | R16: 25 | S16: 0130-00023 | T16: 583 | U16: 99-08 | V16: Banka-015
A17: 45321 | B17: 0130-00023 | C17: 780-01-03 | D17: BANKA MASRAFLARI | E17: 50-01-01 | F17: Banka | G17: ZİRAAT BANK EFT MASRAFI | H17: 30.88 | I17: 0 | J17: 1908.39 | K17: B | O17: 0 | P17: 0 | Q17: 0 | R17: 25 | S17: 0130-00023 | T17: 583 | U17: 99-08 | V17: Banka-015
A18: 45324 | B18: 0202-00020 | C18: 780-01-03 | D18: BANKA MASRAFLARI | F18: Banka | G18: KOMİSYON TAKSİT ÖDEMESİ | H18: 183.75 | I18: 0 | J18: 2092.14 | K18: B | O18: 0 | P18: 0 | Q18: 0 | R18: 25 | S18: 0202-00005 | T18: 768 | V18: Banka-002
A19: 45328 | B19: 0206-00010 | C19: 780-01-03 | D19: BANKA MASRAFLARI | E19: 50-01-01 | F19: Banka | G19: EFT MASRAFI | H19: 572.07 | I19: 0 | J19: 2664.21 | K19: B | O19: 0 | P19: 0 | Q19: 0 | R19: 25 | S19: 0206-00001 | T19: 798 | U19: 99-08 | V19: Banka-015
A20: 45328 | B20: 0206-00011 | C20: 780-01-03 | D20: BANKA MASRAFLARI | E20: 50-01-01 | F20: Banka | G20: EFT MASRAFI | H20: 28.6 | I20: 0 | J20: 2692.81 | K20: B | O20: 0 | P20: 0 | Q20: 0 | R20: 25 | S20: 0206-00002 | T20: 799 | U20: 99-08 | V20: Banka-015
A21: 45335 | B21: 0213-00046 | C21: 780-01-03 | D21: BANKA MASRAFLARI | F21: Banka | G21: EFT MASRAFI-STET | H21: 1325.34 | I21: 0 | J21: 4018.15 | K21: B | N21: EUR | O21: 33.1335 | P21: 40 | Q21: 0 | R21: 65 | S21: 0213-00025 | T21: 949 | V21: Banka-015
A22: 45345 | B22: 0223-00014 | C22: 780-01-03 | D22: BANKA MASRAFLARI | F22: Banka | G22: ZİRAAT BANKA MASRAFI | H22: 0.26 | I22: 0 | J22: 4018.41 | K22: B | O22: 0 | P22: 0 | Q22: 0 | R22: 65 | S22: 0223-00012 | T22: 1128 | V22: Banka-015
A23: 45345 | B23: 0223-00014 | C23: 780-01-03 | D23: BANKA MASRAFLARI | F23: Banka | G23: ZİRAAT BANKA MASRAFI | H23: 0.26 | I23: 0 | J23: 4018.67 | K23: B | O23: 0 | P23: 0 | Q23: 0 | R23: 65 | S23: 0223-00012 | T23: 1128 | V23: Banka-015
A24: 45345 | B24: 0223-00014 | C24: 780-01-03 | D24: BANKA MASRAFLARI | F24: Banka | G24: ZİRAAT BANKA MASRAFI | H24: 0.26 | I24: 0 | J24: 4018.93 | K24: B | O24: 0 | P24: 0 | Q24: 0 | R24: 65 | S24: 0223-00012 | T24: 1128 | V24: Banka-015
A25: 45345 | B25: 0223-00014 | C25: 780-01-03 | D25: BANKA MASRAFLARI | F25: Banka | G25: ZİRAAT BANKA MASRAFI | H25: 0.26 | I25: 0 | J25: 4019.19 | K25: B | O25: 0 | P25: 0 | Q25: 0 | R25: 65 | S25: 0223-00012 | T25: 1128 | V25: Banka-015
A26: 45345 | B26: 0223-00014 | C26: 780-01-03 | D26: BANKA MASRAFLARI | F26: Banka | G26: ZİRAAT BANKA MASRAFI | H26: 0.26 | I26: 0 | J26: 4019.45 | K26: B | O26: 0 | P26: 0 | Q26: 0 | R26: 65 | S26: 0223-00012 | T26: 1128 | V26: Banka-015
A27: 45345 | B27: 0223-00014 | C27: 780-01-03 | D27: BANKA MASRAFLARI | F27: Banka | G27: ZİRAAT BANKA MASRAFI | H27: 0.26 | I27: 0 | J27: 4019.71 | K27: B | O27: 0 | P27: 0 | Q27: 0 | R27: 65 | S27: 0223-00012 | T27: 1128 | V27: Banka-015
A28: 45345 | B28: 0223-00014 | C28: 780-01-03 | D28: BANKA MASRAFLARI | F28: Banka | G28: ZİRAAT BANKA MASRAFI | H28: 0.26 | I28: 0 | J28: 4019.97 | K28: B | O28: 0 | P28: 0 | Q28: 0 | R28: 65 | S28: 0223-00012 | T28: 1128 | V28: Banka-015
A29: 45345 | B29: 0223-00014 | C29: 780-01-03 | D29: BANKA MASRAFLARI | F29: Banka | G29: ZİRAAT BANKA MASRAFI | H29: 0.26 | I29: 0 | J29: 4020.23 | K29: B | O29: 0 | P29: 0 | Q29: 0 | R29: 65 | S29: 0223-00012 | T29: 1128 | V29: Banka-015
A30: 45345 | B30: 0223-00014 | C30: 780-01-03 | D30: BANKA MASRAFLARI | F30: Banka | G30: ZİRAAT BANKA MASRAFI | H30: 0.26 | I30: 0 | J30: 4020.49 | K30: B | O30: 0 | P30: 0 | Q30: 0 | R30: 65 | S30: 0223-00012 | T30: 1128 | V30: Banka-015
A31: 45345 | B31: 0223-00014 | C31: 780-01-03 | D31: BANKA MASRAFLARI | F31: Banka | G31: ZİRAAT BANKA MASRAFI | H31: 0.26 | I31: 0 | J31: 4020.75 | K31: B | O31: 0 | P31: 0 | Q31: 0 | R31: 65 | S31: 0223-00012 | T31: 1128 | V31: Banka-015
A32: 45345 | B32: 0223-00014 | C32: 780-01-03 | D32: BANKA MASRAFLARI | F32: Banka | G32: ZİRAAT BANKA MASRAFI | H32: 0.26 | I32: 0 | J32: 4021.01 | K32: B | O32: 0 | P32: 0 | Q32: 0 | R32: 65 | S32: 0223-00012 | T32: 1128 | V32: Banka-015
A33: 45345 | B33: 0223-00014 | C33: 780-01-03 | D33: BANKA MASRAFLARI | F33: Banka | G33: ZİRAAT BANKA MASRAFI | H33: 0.26 | I33: 0 | J33: 4021.27 | K33: B | O33: 0 | P33: 0 | Q33: 0 | R33: 65 | S33: 0223-00012 | T33: 1128 | V33: Banka-015
... A47: 45350 | B47: 0228-00013 | C47: 780-01-01 | D47: FAİZ GİDERLERİ | F47: Banka | G47: GEKAP VERGİ ÖDEMESİ 2023/07-09 | H47: 59.71 | I47: 0 | J47: 4086.93 | K47: B | O47: 0 | P47: 0 | Q47: 0 | R47: 0 | S47: 0228-00007 | T47: 1218 | V47: Banka-015
A48: 45350 | B48: 0228-00019 | C48: 780-01-03 | D48: BANKA MASRAFLARI | E48: 50-01-01 | F48: Banka | G48: ÇEK TAHSİL ÜCRETİ | H48: 183.75 | I48: 0 | J48: 4270.68 | K48: B | O48: 0 | P48: 0 | Q48: 0 | R48: 65 | S48: 0228-00008 | T48: 1224 | U48: 99-08 | V48: Banka-002
A49: 45350 | B49: 0228-00019 | C49: 780-01-03 | D49: BANKA MASRAFLARI | E49: 50-01-01 | F49: Banka | G49: ÇEK TAHSİL ÜCRETİ | H49: 183.75 | I49: 0 | J49: 4454.43 | K49: B | O49: 0 | P49: 0 | Q49: 0 | R49: 65 | S49: 0228-00008 | T49: 1224 | U49: 99-08 | V49: Banka-002
A50: 45352 | B50: 0301-00022 | C50: 780-01-03 | D50: BANKA MASRAFLARI | F50: Banka | G50: IBKB MASRAFI | H50: 31.87 | I50: 0 | J50: 4486.3 | K50: B | O50: 0 | P50: 0 | Q50: 0 | R50: 65 | S50: 0301-00009 | T50: 1325 | V50: Banka-015
A51: 45352 | B51: 0301-00022 | C51: 780-01-03 | D51: BANKA MASRAFLARI | F51: Banka | G51: IBKB MASRAFI | H51: 31.87 | I51: 0 | J51: 4518.17 | K51: B | O51: 0 | P51: 0 | Q51: 0 | R51: 65 | S51: 0301-00009 | T51: 1325 | V51: Banka-015
A52: 45352 | B52: 0301-00022 | C52: 780-01-03 | D52: BANKA MASRAFLARI | F52: Banka | G52: IBKB MASRAFI | H52: 31.87 | I52: 0 | J52: 4550.04 | K52: B | O52: 0 | P52: 0 | Q52: 0 | R52: 65 | S52: 0301-00009 | T52: 1325 | V52: Banka-015
A53: 45352 | B53: 0301-00029 | C53: 780-01-03 | D53: BANKA MASRAFLARI | F53: Banka | G53: LTD TRIADA GELEN BANKA ÖDEMESİ | H53: 0 | I53: 159.22 | J53: 4390.82 | K53: B | N53: USD | O53: 31.1597 | P53: 0 | Q53: 5.11 | R53: 59.89 | S53: 0301-00012 | T53: 1332 | V53: Banka-015
A54: 45352 | B54: 0301-00030 | C54: 780-01-03 | D54: BANKA MASRAFLARI | F54: Banka | G54: MUHABİR MASRAFI | H54: 118.19 | I54: 0 | J54: 4509.01 | K54: B | N54: EUR | O54: 0 | P54: 3.5 | Q54: 0 | R54: 63.39 | S54: 0301-00013 | T54: 1333 | V54: Banka-015
...

Sheet FGK
B1: FİNANSMAN GİDER KISITLAMASI HESAP TUTARLARI
B2: 780 Hesap | C2: 0
B3: 660 Hesap | C3: 0
B4: 656 Hesap | C4: 0
B5: TOPLAM | C5: =SUM(C2:C4) -> 0
B11: FİNANSMAN GİDER KISITLAMASI HESAPLAMA
A12: 1 | B12: Özsermeye tutarı * | C12: =+BİLANÇO!F141 -> 13796354 | D12: *1. satırdaki özsermaye tutarı negatif ise; 0 (sıfır) olarak değerlendirilecektir.
A13: 2 | B13: Yabancı kaynak toplamı (Aktif-Özsermaye) | C13: =+BİLANÇO!C143-FGK!C12 -> 29002519
A14: 3 | B14: Özsermayeyi aşan yabancı kaynak tutarı (2-1) * | C14: =+C13-C12 -> 15206165 | D14: *3. satırdaki tutar sıfır yada eksi olursa gider kısıtlaması yapılmayacaktır.
A15: 4 | B15: Aşan kısmın yabancı kaynağa oranı (3/2) | C15: =C14/C13 -> 0.52430498
A16: 5 | B16: Finansman gider tutarı (780,660,656 ..vb hesaplar) | C16: 0
A17: 6 | B17: Örtülü sermayeye ait finansman gideri (KKEG)(örtülü sermaye var ise) | C17: 0
A18: 7 | B18: Hesaplamada dikkate alınacak finansman gideri (5-6) | C18: =+C5 -> 0
A19: 8 | B19: Aşan kısma isabet eden finansman gideri (4*7) | C19: =C15*C18 -> 0
A20: 9 | B20: KKEG olacak finansman giderleri (8*%10) | C20: =C19*0.1 -> 0 | D20: =IF(C14<=0,"FİNANSMAN GİDER KISITLAMASI UYGULANMAYACAK","KKEG YAZILACAK FİNANSMAN GİDERİ") -> KKEG YAZILACAK FİNANSMAN GİDERİ
B26: *1. satırdaki özsermaye tutarı negatif ise; 0 (sıfır) olarak değerlendirilecektir.
B27: *3. satırdaki tutar sıfır yada eksi olursa gider kısıtlaması yapılmayacaktır.
B29: Finansman Giderleri
B30: Yabancı kaynağın kullanım süresine bağlı olarak doğan her türlü faiz, komisyon, vade farkı, kâr payı, kur farkı, faktoring kuruluşlarına verilen iskonto bedelleri ve benzeri adlar altında yapılmış olan gider ve maliyet unsurlarından oluşur. Bu tutarların yer aldığı 780, 660, 656 hesaplar ve benzeri hesaplardaki rakamlar kısıtlamaya tabi olacak.
B31: Özsermaye
B32: Gider kısıtlamasının yapılacağı dönem itibariyle çıkarılan bilançodaki özsermaye olup, her dönem sonu itibariyle bilanço çıkarılması gerekiyor. Ör. 2021/1. Geçici için 31.03.2021 tarihli bilançodaki özsermaye dikkate alınacak.
B33: Yabancı Kaynaklar
B34: Bilançonun kısa vadeli yabancı kaynaklar ve uzun vadeli yabancı kaynaklar toplamını ifade etmekte. (Aktif-Özsermaye)
B35: Finansman Gider Kıstlamasına tabi olmayan giderler
B36: Teminat mektubu komisyonları, tahvil ihracı ile ilgili olarak yapılan baskı ve benzeri giderler ile ipotek masrafları gibi herhangi bir yabancı kaynak kullanımına bağlı olmaksızın yapılan giderlerin gider kısıtlamasına konu edilmesi söz konusu değildir. Aynı şekilde bir finansman gideri olmayıp finansman geliri azalması niteliğinde olan erken ödeme iskontoları veya peşin ödeme iskontoları da gider indirimi kısıtlaması kapsamı dışındadır.
B37: kredi sözleşmelerine ilişkin olarak ödenen damga vergisi veya banka havale ücretlerine ilişkin ödenen banka ve sigorta muameleleri vergisi gibi bir yabancı kaynağın kullanım süresine bağlı olarak doğmayan gider ve maliyet unsurları gider indirimi kısıtlaması uygulamasına tabi olmayacaktır.
B38: Yapılmakta Olan Yatırımlara ait finansman giderleri
... B42: Gelir tablosunda yer alan doğrudan finansman giderleri kısıtlamaya tabi olacaktır. Bu giderler içinden yatırım maliyetine aktarılan tutar olursa, aktarılan tutar gider kısıtlamasına tabi olmayacak, kalan tutar kısıtlamada dikkate alınacaktır.

Sheet KKEG
A1: Muhasebe Hareket Bilgileri (mhy03)
A3: Fiş Tarihi | B3: Fiş No | C3: Hesap Kodu | D3: Hesap Adı | E3: Kar Merkezi Kodu | F3: Kaynak Yeri | G3: Açıklama | H3: Borç Tutarı | I3: Alacak Tutarı | J3: Bakiye | K3: B/A | L3: Özel Kod-1 | M3: Özel Kod-2 | N3: Döviz | O3: Döviz Kuru | P3: Döviz Borç | Q3: Döviz Alacak | R3: Döviz Bakiye | S3: Birleştirilmiş Fiş No | T3: Madde No | U3: Gelir/Gider Kodu | V3: Analiz Kodu | W3: Proje Kodu | X3: Proje Tipi | Y3: İşyeri Kodu
A4: 45292 | B4: 0101-00001 | C4: 689-01-90 | D4: KANUNEN KABUL EDİLMEYEN GİDERLER | E4: ÖİV | F4: Fatura | G4: YBB2024010102751 TURKNET İLETİŞİM HİZMET | H4: 45.95 | I4: 0 | J4: 45.95 | K4: B | O4: 0 | P4: 0 | Q4: 0 | R4: 0 | T4: 1
A5: 45294 | B5: 0103-00019 | C5: 689-01-90 | D5: KANUNEN KABUL EDİLMEYEN GİDERLER | E5: ARAÇ G.K. | F5: Fatura | G5: GNY2024000000001 GÜNEYLİ OTOMOBİL OTO SE | H5: 3820.5 | I5: 0 | J5: 3911.45 | K5: B | O5: 0 | P5: 0 | Q5: 0 | R5: 0 | T5: 57
A6: 45294 | B6: 0103-00004 | C6: 689-01-90 | D6: KANUNEN KABUL EDİLMEYEN GİDERLER | E6: ARAÇ G.K. | F6: Banka | G6: OTOMATIK Plaka no: 34FDF874 , 1117437630 | H6: 22.5 | I6: 0 | J6: 68.45 | K6: B | O6: 0 | P6: 0 | Q6: 0 | R6: 0 | S6: 0103-00002 | T6: 42
A7: 45294 | B7: 0103-00005 | C7: 689-01-90 | D7: KANUNEN KABUL EDİLMEYEN GİDERLER | E7: ARAÇ G.K. | F7: Banka | G7: OTOMATIK Plaka no: 34FDF874 , 1117437630 | H7: 22.5 | I7: 0 | J7: 90.95 | K7: B | O7: 0 | P7: 0 | Q7: 0 | R7: 0 | S7: 0103-00003 | T7: 43
A8: 45295 | B8: 0104-00003 | C8: 689-01-90 | D8: KANUNEN KABUL EDİLMEYEN GİDERLER | E8: ARAÇ G.K. | F8: Banka | G8: OTOMATIK Plaka no: 34FDF874 , 1117437630 | H8: 22.5 | I8: 0 | J8: 3933.95 | K8: B | O8: 0 | P8: 0 | Q8: 0 | R8: 0 | S8: 0104-00002 | T8: 76
A9: 45296 | B9: 0105-00011 | C9: 689-01-05 | D9: TAZMİNAT VE CEZA GİDERLERİ | E9: DİĞER | F9: Banka | G9: 12/12/23-85985303 SGK IPC BORÇ ÖDEME | H9: 2846.05 | I9: 0 | J9: 6780 | K9: B | O9: 0 | P9: 0 | Q9: 0 | R9: 0 | S9: 0105-00003 | T9: 106
A10: 45298 | B10: 0107-00001 | C10: 689-01-90 | D10: KANUNEN KABUL EDİLMEYEN GİDERLER | E10: ARAÇ G.K. | F10: Banka | G10: OTOMATIK Plaka no: 34FDF874 , 1117437630 | H10: 22.5 | I10: 0 | J10: 6802.5 | K10: B | O10: 0 | P10: 0 | Q10: 0 | R10: 0 | S10: 0107-00001 | T10: 125
A11: 45299 | B11: 0108-00048 | C11: 689-01-03 | D11: KURUŞ ELEMİNELERİ-GİDER | E11: DİĞER | F11: Fatura | G11: KRK2024000000002 KARACA HIRDAVAT CİVATA | H11: 0.02 | I11: 0 | J11: 6802.52 | K11: B | O11: 0 | P11: 0 | Q11: 0 | R11: 0 | T11: 174
A12: 45300 | B12: 0109-00002 | C12: 689-01-90 | D12: KANUNEN KABUL EDİLMEYEN GİDERLER | E12: ARAÇ G.K. | F12: Banka | G12: OTOMATIK Plaka no: 34CZE831 , 1117318885 | H12: 22.5 | I12: 0 | J12: 6825.02 | K12: B | O12: 0 | P12: 0 | Q12: 0 | R12: 0 | S12: 0109-00001 | T12: 176
A13: 45300 | B13: 0109-00004 | C13: 689-01-90 | D13: KANUNEN KABUL EDİLMEYEN GİDERLER | E13: ARAÇ G.K. | F13: Banka | G13: OTOMATIK Plaka no: 34GS0987 , 1113247685 | H13: 42 | I13: 0 | J13: 6867.02 | K13: B | O13: 0 | P13: 0 | Q13: 0 | R13: 0 | S13: 0109-00002 | T13: 178
A14: 45301 | B14: 0110-00024 | C14: 689-01-90 | D14: KANUNEN KABUL EDİLMEYEN GİDERLER | E14: DİĞER | F14: Fatura | G14: AAA2024000000844 BATI KURUMSAL TEDARİK Ç | H14: 3721.39 | I14: 0 | J14: 10588.41 | K14: B | O14: 0 | P14: 0 | Q14: 0 | R14: 0 | T14: 216
A15: 45302 | B15: 0111-00004 | C15: 689-01-90 | D15: KANUNEN KABUL EDİLMEYEN GİDERLER | E15: ARAÇ G.K. | F15: Banka | G15: OTOMATIK Plaka no: 34FDF874 , 1117437630 | H15: 22.5 | I15: 0 | J15: 10640.91 | K15: B | O15: 0 | P15: 0 | Q15: 0 | R15: 0 | S15: 0111-00002 | T15: 228
A16: 45302 | B16: 0111-00003 | C16: 689-01-90 | D16: KANUNEN KABUL EDİLMEYEN GİDERLER | E16: ARAÇ G.K. | F16: Banka | G16: OTOMATIK Plaka no: 34GS0987 , 1113247685 | H16: 30 | I16: 0 | J16: 10618.41 | K16: B | O16: 0 | P16: 0 | Q16: 0 | R16: 0 | S16: 0111-00001 | T16: 227
A17: 45304 | B17: 0113-00001 | C17: 689-01-90 | D17: KANUNEN KABUL EDİLMEYEN GİDERLER | E17: ARAÇ G.K. | F17: Banka | G17: OTOMATIK Plaka no: 34FMA593 , 1117685178 | H17: 60 | I17: 0 | J17: 10700.91 | K17: B | O17: 0 | P17: 0 | Q17: 0 | R17: 0 | S17: 0113-00001 | T17: 290
A18: 45305 | B18: 0114-00001 | C18: 689-01-90 | D18: KANUNEN KABUL EDİLMEYEN GİDERLER | E18: ARAÇ G.K. | F18: Banka | G18: OTOMATIK Plaka no: 34FDF874 , 1117437630 | H18: 22.5 | I18: 0 | J18: 10723.41 | K18: B | O18: 0 | P18: 0 | Q18: 0 | R18: 0 | S18: 0114-00001 | T18: 294
A19: 45308 | B19: 0117-00013 | C19: 689-01-90 | D19: KANUNEN KABUL EDİLMEYEN GİDERLER | E19: ARAÇ G.K. | F19: Banka | G19: OTOMATIK Plaka no: 34FDF874 , 1117437630 | H19: 22.5 | I19: 0 | J19: 10775.91 | K19: B | O19: 0 | P19: 0 | Q19: 0 | R19: 0 | S19: 0117-00003 | T19: 344
A20: 45308 | B20: 0117-00014 | C20: 689-01-90 | D20: KANUNEN KABUL EDİLMEYEN GİDERLER | E20: ARAÇ G.K. | F20: Banka | G20: OTOMATIK Plaka no: 34FDF874 , 1117437630 | H20: 22.5 | I20: 0 | J20: 10798.41 | K20: B | O20: 0 | P20: 0 | Q20: 0 | R20: 0 | S20: 0117-00004 | T20: 345
A21: 45308 | B21: 0117-00015 | C21: 689-01-90 | D21: KANUNEN KABUL EDİLMEYEN GİDERLER | E21: ARAÇ G.K. | F21: Banka | G21: OTOMATIK Plaka no: 34FDF874 , 1117437630 | H21: 34.5 | I21: 0 | J21: 10832.91 | K21: B | O21: 0 | P21: 0 | Q21: 0 | R21: 0 | S21: 0117-00005 | T21: 346
A22: 45308 | B22: 0117-00011 | C22: 689-01-90 | D22: KANUNEN KABUL EDİLMEYEN GİDERLER | E22: ARAÇ G.K. | F22: Banka | G22: OTOMATIK Plaka no: 34GS0987 , 1113247685 | H22: 30 | I22: 0 | J22: 10753.41 | K22: B | O22: 0 | P22: 0 | Q22: 0 | R22: 0 | S22: 0117-00001 | T22: 342
A23: 45309 | B23: 0118-00008 | C23: 689-01-90 | D23: KANUNEN KABUL EDİLMEYEN GİDERLER | E23: ARAÇ G.K. | F23: Banka | G23: OTOMATIK Plaka no: 34GS0987 , 1113247685 | H23: 43.5 | I23: 0 | J23: 10892.01 | K23: B | O23: 0 | P23: 0 | Q23: 0 | R23: 0 | S23: 0118-00003 | T23: 367
A24: 45309 | B24: 0118-00003 | C24: 689-01-90 | D24: KANUNEN KABUL EDİLMEYEN GİDERLER | E24: DİĞER | F24: Fatura | G24: DP-F-0011 FURKAN SANCAR / İŞ AVANSI | H24: 15.6 | I24: 0 | J24: 10848.51 | K24: B | O24: 0 | P24: 0 | Q24: 0 | R24: 0 | T24: 362
A25: 45310 | B25: 0119-00042 | C25: 689-01-90 | D25: KANUNEN KABUL EDİLMEYEN GİDERLER | E25: ARAÇ G.K. | F25: Banka | G25: OTOMATIK Plaka no: 34GS0987 , 1113247685 | H25: 30 | I25: 0 | J25: 12962.02 | K25: B | O25: 0 | P25: 0 | Q25: 0 | R25: 0 | S25: 0119-00020 | T25: 416
A26: 45310 | B26: 0119-00022 | C26: 689-01-90 | D26: KANUNEN KABUL EDİLMEYEN GİDERLER | E26: DİĞER | F26: Fatura | G26: GAD2024000000029 KREDİ KARTI SATICILARI | H26: 2040.01 | I26: 0 | J26: 12932.02 | K26: B | O26: 0 | P26: 0 | Q26: 0 | R26: 0 | T26: 396 | U26: 99-07
A27: 45311 | B27: 0120-00007 | C27: 689-01-90 | D27: KANUNEN KABUL EDİLMEYEN GİDERLER | E27: ARAÇ G.K. | F27: Fatura | G27: BAE2024000001005 BATI KURUMSAL TEDARİK Ç | H27: 3229.72 | I27: 0 | J27: 16244.24 | K27: B | O27: 0 | P27: 0 | Q27: 0 | R27: 0 | T27: 423
A28: 45311 | B28: 0120-00003 | C28: 689-01-90 | D28: KANUNEN KABUL EDİLMEYEN GİDERLER | E28: ARAÇ G.K. | F28: Banka | G28: OTOMATIK Plaka no: 34EME494 , 1117318887 | H28: 22.5 | I28: 0 | J28: 13014.52 | K28: B | O28: 0 | P28: 0 | Q28: 0 | R28: 0 | S28: 0120-00002 | T28: 419
A29: 45311 | B29: 0120-00002 | C29: 689-01-90 | D29: KANUNEN KABUL EDİLMEYEN GİDERLER | E29: ARAÇ G.K. | F29: Banka | G29: OTOMATIK Plaka no: 34GS0987 , 1113247685 | H29: 30 | I29: 0 | J29: 12992.02 | K29: B | O29: 0 | P29: 0 | Q29: 0 | R29: 0 | S29: 0120-00001 | T29: 418
A30: 45314 | B30: 0123-00007 | C30: 689-01-90 | D30: KANUNEN KABUL EDİLMEYEN GİDERLER | E30: ARAÇ G.K. | F30: Banka | G30: OTOMATIK Plaka no: 34EME494 , 1117318887 | H30: 22.5 | I30: 0 | J30: 16266.74 | K30: B | O30: 0 | P30: 0 | Q30: 0 | R30: 0 | S30: 0123-00001 | T30: 452
A31: 45315 | B31: 0124-00017 | C31: 689-01-90 | D31: KANUNEN KABUL EDİLMEYEN GİDERLER | E31: ARAÇ G.K. | F31: Banka | G31: OTOMATIK Plaka no: 34GS0987 , 1113247685 | H31: 52.5 | I31: 0 | J31: 31365.57 | K31: B | O31: 0 | P31: 0 | Q31: 0 | R31: 0 | S31: 0124-00007 | T31: 476
A32: 45315 | B32: 0124-00018 | C32: 689-01-90 | D32: KANUNEN KABUL EDİLMEYEN GİDERLER | E32: ARAÇ G.K. | F32: Banka | G32: OTOMATIK Plaka no: 34GS0987 , 1113247685 | H32: 52.5 | I32: 0 | J32: 31418.07 | K32: B | O32: 0 | P32: 0 | Q32: 0 | R32: 0 | S32: 0124-00008 | T32: 477
A33: 45315 | B33: 0124-00012 | C33: 689-01-90 | D33: KANUNEN KABUL EDİLMEYEN GİDERLER | E33: DİĞER | F33: Fatura | G33: LDE2024000008230 KREDİ KARTI SATICILARI | H33: 1173.33 | I33: 0 | J33: 31313.07 | K33: B | O33: 0 | P33: 0 | Q33: 0 | R33: 0 | T33: 471 | U33: 99-07
A34: 45315 | B34: 0124-00004 | C34: 689-01-90 | D34: KANUNEN KABUL EDİLMEYEN GİDERLER | E34: MTV | F34: Banka | G34: 06FY6809 MTV ÖDEMESİ | H34: 1272 | I34: 0 | J34: 19554.74 | K34: B | O34: 0 | P34: 0 | Q34: 0 | R34: 0 | S34: 0124-00002 | T34: 463
A35: 45315 | B35: 0124-00004 | C35: 689-01-90 | D35: KANUNEN KABUL EDİLMEYEN GİDERLER | E35: MTV | F35: Banka | G35: 34CZE831 MTV ÖDEMESİ | H35: 1288 | I35: 0 | J35: 20842.74 | K35: B | O35: 0 | P35: 0 | Q35: 0 | R35: 0 | S35: 0124-00002 | T35: 463
A36: 45315 | B36: 0124-00004 | C36: 689-01-90 | D36: KANUNEN KABUL EDİLMEYEN GİDERLER | E36: MTV | F36: Banka | G36: 34EME494 MTV ÖDEMESİ | H36: 2632.5 | I36: 0 | J36: 23475.24 | K36: B | O36: 0 | P36: 0 | Q36: 0 | R36: 0 | S36: 0124-00002 | T36: 463
A37: 45315 | B37: 0124-00004 | C37: 689-01-90 | D37: KANUNEN KABUL EDİLMEYEN GİDERLER | E37: MTV | F37: Banka | G37: 34FDF874 MTV ÖDEMESİ | H37: 2016 | I37: 0 | J37: 27507.24 | K37: B | O37: 0 | P37: 0 | Q37: 0 | R37: 0 | S37: 0124-00002 | T37: 463
A38: 45315 | B38: 0124-00004 | C38: 689-01-90 | D38: KANUNEN KABUL EDİLMEYEN GİDERLER | E38: MTV | F38: Banka | G38: 34FMA593 MTV ÖDEMESİ | H38: 2016 | I38: 0 | J38: 25491.24 | K38: B | O38: 0 | P38: 0 | Q38: 0 | R38: 0 | S38: 0124-00002 | T38: 463
A39: 45315 | B39: 0124-00004 | C39: 689-01-90 | D39: KANUNEN KABUL EDİLMEYEN GİDERLER | E39: MTV | F39: Banka | G39: 34GHZ549 MTV ÖDEMESİ | H39: 2016 | I39: 0 | J39: 18282.74 | K39: B | O39: 0 | P39: 0 | Q39: 0 | R39: 0 | S39: 0124-00002 | T39: 463
A40: 45315 | B40: 0124-00004 | C40: 689-01-90 | D40: KANUNEN KABUL EDİLMEYEN GİDERLER | E40: MTV | F40: Banka | G40: 34GS0987 MTV ÖDEMESİ | H40: 2632.5 | I40: 0 | J40: 30139.74 | K40: B | O40: 0 | P40: 0 | Q40: 0 | R40: 0 | S40: 0124-00002 | T40: 463
A41: 45316 | B41: 0125-00009 | C41: 689-01-90 | D41: KANUNEN KABUL EDİLMEYEN GİDERLER | E41: ARAÇ G.K. | F41: Banka | G41: OTOMATIK Plaka no: 06FY6809 , 1117318886 | H41: 52.5 | I41: 0 | J41: 31733.07 | K41: B | O41: 0 | P41: 0 | Q41: 0 | R41: 0 | S41: 0125-00006 | T41: 502
...

Sheet GEÇMİŞ DÖNEM ZARARLARI
B3: DÖNEM | C3: ZARAR | D3: KKEG | E3: KAR | F3: KARDAN DÜŞÜLECEK ZARAR
B4: 2019 | F4: =+C4-D4 -> 0
B5: 2020 | F5: 0
B6: 2021 | F6: 0
B7: 2022 | F7: 0
B8: 2023 | F8: =+C8-D8 -> 0
B9: TOPLAM | C9: =SUM(C4:C8) -> 0 | D9: =SUM(D4:D8) -> 0 | E9: =SUM(E4:E8) -> 0

Sheet KVK GEÇ 32-8
C5: VERGİ MATRAHI | D5: 0
B7: HESAP KODU | C7: BRÜT SATIŞLAR TOPLAMI | D7: TUTAR | E7: YÜZDE | F7: VERGİ MATRAHI
B8: 600 | C8: YURTİÇİ SATIŞLAR | D8: 0 | E8: =D8/D11 -> #DIV/0! | F8: #DIV/0! | G8: ÜRETİMDEN ELDE EDİLEN KAZANÇ | H8: KVK 32/8 E YAZILACAK TUTAR
B9: 601 | C9: YURTDIŞI SATIŞLAR | D9: 0 | E9: =D9/D11 -> #DIV/0! | F9: =$D$5*E9 -> #DIV/0!
B10: 602 | C10: DİĞER GELİRLER | D10: 0 | E10: =D10/D11 -> #DIV/0! | F10: =$D$5*E10 -> #DIV/0!
C11: TOPLAM | D11: =SUM(D8:D10) -> 0 | F11: =SUM(F8:F10) -> #DIV/0!
C16: ÖZET TABLO
C17: GELİR TÜRÜ | D17: MATRAH | E17: ORAN | F17: VERGİ
C18: KVK 32/8 MATRAH | D18: =+F8 -> #DIV/0! | E18: 0.24 | F18: =D18*E18 -> #DIV/0!
C19: DİĞER MATRAH | D19: =+D5-D18 -> #DIV/0! | E19: 0.25 | F19: =D19*E19 -> #DIV/0!
C20: TOPLAM | D20: =SUM(D18:D19) -> #DIV/0! | F20: =SUM(F18:F19) -> #DIV/0!
