Workbook

Sheet 30.06.2024 Bilanço  
A4: TAVUK DÜNYASI GIDA SAN VE TİC. A.Ş. 30/06/2024
A5: TEK DÜZEN HESAP PLANI AYRINTILI BİLANÇO(TL)
D7: AKTİF | L7: PASİF
G10: 45473 | O10: 45473
A12: I. | D12: DÖNEN VARLIKLAR | G12: =+G14+G22+G33+G41+G52+G55 -> 1.2890713e+09 | I12: III. | L12: KISA VADELİ YABANCI KAYNAKLAR | O12: =+O14+O20+O27+O32+O36+O41+O47+O51 -> 1.1920696e+09
B14: .A. | D14: Hazır Değerler | G14: =SUM(G15:G21) -> 6.047565e+08 | J14: .A. | L14: Mali Borçlar | O14: =SUM(O15:O18) -> 5.751963e+08
C15: .1. | D15: Kasa | E15: 100 | G15: =IFERROR(VLOOKUP(E15,'30.06.2024 Ana Hs.Mizanı S'!A:G,7,0),0) -> 492417 | K15: .1. | L15: Banka Kredileri | M15: 300 | O15: =-IFERROR(VLOOKUP(M15,'30.06.2024 Ana Hs.Mizanı S'!A:G,7,0),0) -> 5.7460138e+08
C16: .2. | D16: Alınan Çekler | E16: 101 | G16: =IFERROR(VLOOKUP(E16,'30.06.2024 Ana Hs.Mizanı S'!A:G,7,0),0) -> 1.0118489e+08 | K16: .2. | L16: Finansal Kiralama İşlemlerinden Borçlar | M16: 301 | O16: =-IFERROR(VLOOKUP(M16,'30.06.2024 Ana Hs.Mizanı S'!A:G,7,0),0) -> 0
C17: .3. | D17: Bankalar | E17: 102 | G17: =IFERROR(VLOOKUP(E17,'30.06.2024 Ana Hs.Mizanı S'!A:G,7,0),0) -> 3.7024815e+08 | K17: .3. | L17: Ertelenmiş Finansal Kiralama Borçlanma Maliyetleri | M17: 302 | O17: =-IFERROR(VLOOKUP(M17,'30.06.2024 Ana Hs.Mizanı S'!A:G,7,0),0) -> 0
C18: .4. | D18: Verilen çekler ve ödeme emirleri (-) | E18: 103 | G18: =IFERROR(VLOOKUP(E18,'30.06.2024 Ana Hs.Mizanı S'!A:G,7,0),0) -> 0 | K18: .4. | L18: Diğer Mali Borçlar | M18: 309 | O18: =-IFERROR(VLOOKUP(M18,'30.06.2024 Ana Hs.Mizanı S'!A:G,7,0),0) -> 594919.36
C19: .5. | D19: Diğer Hazır Değerler | E19: 108 | G19: =IFERROR(VLOOKUP(E19,'30.06.2024 Ana Hs.Mizanı S'!A:G,7,0),0) -> 3498049.2
C20: .6. | D20: Özel Kesim Tahvil, Senet Ve Bonoları | E20: 111 | G20: =IFERROR(VLOOKUP(E20,'30.06.2024 Ana Hs.Mizanı S'!A:G,7,0),0) -> 71250609 | J20: .B. | L20: Ticari Borçlar | O20: =SUM(O22:O25) -> 4.1918826e+08
C21: .7. | D21: Diğer Hazır Menkul Kıymetler | E21: 118 | G21: =IFERROR(VLOOKUP(E21,'30.06.2024 Ana Hs.Mizanı S'!A:G,7,0),0) -> 58082389
B22: .B. | D22: Ticari Alacaklar | G22: =SUM(G24:G31) -> 3.4961751e+08 | K22: .1. | L22: Satıcılar | M22: 320 | O22: =-IFERROR(VLOOKUP(M22,'30.06.2024 Ana Hs.Mizanı S'!A:G,7,0),0) -> 2.9457346e+08
K23: .2. | L23: Borç Senetleri | M23: 321 | O23: =-IFERROR(VLOOKUP(M23,'30.06.2024 Ana Hs.Mizanı S'!A:G,7,0),0) -> 1.2455743e+08
C24: .1. | D24: Alıcılar | E24: 120 | G24: =IFERROR(VLOOKUP(E24,'30.06.2024 Ana Hs.Mizanı S'!A:G,7,0),0) -> 3.0750284e+08 | K24: .3. | L24: Alınan Depozito ve Teminatlar | M24: 326 | O24: =-IFERROR(VLOOKUP(M24,'30.06.2024 Ana Hs.Mizanı S'!A:G,7,0),0) -> 0
C25: .2. | D25: Alacak Senetleri | E25: 121 | G25: =IFERROR(VLOOKUP(E25,'30.06.2024 Ana Hs.Mizanı S'!A:G,7,0),0) -> 0 | K25: .4. | L25: Diğer Ticari Borçlar | M25: 329 | O25: =-IFERROR(VLOOKUP(M25,'30.06.2024 Ana Hs.Mizanı S'!A:G,7,0),0) -> 57366.03
C26: .3. | D26: Alacak Senetleri Reeskontu | E26: 122 | G26: =IFERROR(VLOOKUP(E26,'30.06.2024 Ana Hs.Mizanı S'!A:G,7,0),0) -> 0
C27: .4. | D27: Verilen Depozito ve teminatlar | E27: 126 | G27: =IFERROR(VLOOKUP(E27,'30.06.2024 Ana Hs.Mizanı S'!A:G,7,0),0) -> 38535728 | J27: .C. | L27: Diğer Borçlar | O27: =SUM(O28:O30) -> 54058228
K28: .1. | L28: Ortaklara Borçlar | M28: 331 | O28: =-IFERROR(VLOOKUP(M28,'30.06.2024 Ana Hs.Mizanı S'!A:G,7,0),0) -> 0 | U28: KVYK+UVYK | W28: =O12+O55 -> 1.2040554e+09
C29: .5. | D29: Diğer Ticari Alacaklar | E29: 127 | G29: =IFERROR(VLOOKUP(E29,'30.06.2024 Ana Hs.Mizanı S'!A:G,7,0),0) -> 3578938.2 | K29: .2. | L29: Personele Borçlar | M29: 335 | O29: =-IFERROR(VLOOKUP(M29,'30.06.2024 Ana Hs.Mizanı S'!A:G,7,0),0) -> 27799645
C30: .6. | D30: Şüpheli Ticari Alacaklar | E30: 128 | G30: =IFERROR(VLOOKUP(E30,'30.06.2024 Ana Hs.Mizanı S'!A:G,7,0),0) -> 0 | K30: .3. | L30: Diğer Çeşitli Borçlar | M30: 336 | O30: =-IFERROR(VLOOKUP(M30,'30.06.2024 Ana Hs.Mizanı S'!A:G,7,0),0) -> 26258583
C31: .7. | D31: Şüpheli Ticari Alacaklar Karşılığı (-) | E31: 129 | G31: =IFERROR(VLOOKUP(E31,'30.06.2024 Ana Hs.Mizanı S'!A:G,7,0),0) -> 0
J32: .D. | L32: Alınan Avanslar | O32: =SUM(O33)+O34 -> 42945092 | U32: ÖZKAYNAK | W32: =O69*1 -> 1.6530749e+09
B33: .C. | D33: Diğer Alacaklar | G33: =SUM(G34:G38) -> 15380817 | K33: .1. | L33: Alınan Sipariş Avansları | M33: 340 | O33: =-IFERROR(VLOOKUP(M33,'30.06.2024 Ana Hs.Mizanı S'!A:G,7,0),0) -> 3387942.7
C34: .1. | D34: Ortaklardan Alacaklar | E34: 131 | G34: =IFERROR(VLOOKUP(E34,'30.06.2024 Ana Hs.Mizanı S'!A:G,7,0),0) -> 0 | K34: 2. | L34: Alınan Diğer Avanslar | M34: 349 | O34: =-IFERROR(VLOOKUP(M34,'30.06.2024 Ana Hs.Mizanı S'!A:G,7,0),0) -> 39557150
C35: .2. | D35: Personelden Alacaklar | E35: 135 | G35: =IFERROR(VLOOKUP(E35,'30.06.2024 Ana Hs.Mizanı S'!A:G,7,0),0) -> 10070654
C36: .3. | D36: Diğer Çeşitli Alacaklar | E36: 136 | G36: =IFERROR(VLOOKUP(E36,'30.06.2024 Ana Hs.Mizanı S'!A:G,7,0),0) -> 5263164 | J36: .E. | L36: Ödenecek Vergi ve Diğer Yükümlülükler | O36: =SUM(O37:O40) -> 46549671
C37: .4. | D37: Şüpheli Diğer Alacaklar | E37: 138 | G37: =IFERROR(VLOOKUP(E37,'30.06.2024 Ana Hs.Mizanı S'!A:G,7,0),0) -> 143839.03 | K37: .1. | L37: Ödenecek Vergi ve Fonlar | M37: 360 | O37: =-IFERROR(VLOOKUP(M37,'30.06.2024 Ana Hs.Mizanı S'!A:G,7,0),0) -> 18410728
C38: .5. | D38: Şüpheli Diğer Alacaklar Karşılığı (-) | E38: 139 | G38: =IFERROR(VLOOKUP(E38,'30.06.2024 Ana Hs.Mizanı S'!A:G,7,0),0) -> -96840.41 | K38: .2. | L38: Ödenecek Sosyal Güvenlik Kesintileri | M38: 361 | O38: =-IFERROR(VLOOKUP(M38,'30.06.2024 Ana Hs.Mizanı S'!A:G,7,0),0) -> 27869076
K39: .3. | L39: Vadesi Geçmiş, Ertelenen veya Taksitlendirilmiş Vergi | M39: 368 | O39: =-IFERROR(VLOOKUP(M39,'30.06.2024 Ana Hs.Mizanı S'!A:G,7,0),0) -> 0
K40: .4. | L40: Ödenecek Diğer Yükümlülükler | M40: 369 | O40: =-IFERROR(VLOOKUP(M40,'30.06.2024 Ana Hs.Mizanı S'!A:G,7,0),0) -> 269867
B41: .D. | D41: Stoklar | G41: =SUM(G45:G50) -> 2.1813938e+08 | J41: .F. | L41: Diğer Borç ve gider karşılıkları | O41: =SUM(O42:O45) -> 8234135.5
K42: .1. | L42: Dönem Karı Vergi ve Diğ.Yas.Yük. Karşılıkları | M42: 370 | O42: =-IFERROR(VLOOKUP(M42,'30.06.2024 Ana Hs.Mizanı S'!A:G,7,0),0) -> 0
K43: .2. | L43: Dön.Kar.Peşin Öd.Vergi ve Diğer Yükümlülükler | M43: 371 | O43: =-IFERROR(VLOOKUP(M43,'30.06.2024 Ana Hs.Mizanı S'!A:G,7,0),0) -> 0
K44: .3. | L44: Mliyet Giderleri Karşılığı | M44: 373 | O44: =-IFERROR(VLOOKUP(M44,'30.06.2024 Ana Hs.Mizanı S'!A:G,7,0),0) -> 0
C45: .1. | D45: İlk Madde Malzemeler | E45: 150 | G45: =IFERROR(VLOOKUP(E45,'30.06.2024 Ana Hs.Mizanı S'!A:G,7,0),0) -> 29294774 | K45: .4. | L45: Diğer Borç ve gider karşılıkları | M45: 379 | O45: =-IFERROR(VLOOKUP(M45,'30.06.2024 Ana Hs.Mizanı S'!A:G,7,0),0) -> 8234135.5
C46: .2. | D46: Yarı Mamüller | E46: 151 | G46: =IFERROR(VLOOKUP(E46,'30.06.2024 Ana Hs.Mizanı S'!A:G,7,0),0) -> 50243385
C47: .3. | D47: Mamüller | E47: 152 | G47: =IFERROR(VLOOKUP(E47,'30.06.2024 Ana Hs.Mizanı S'!A:G,7,0),0) -> 0 | J47: .G. | L47: Gelecek Aylara Ait Gelirler ve Gider Tahakkukları | O47: =SUM(O48:O49) -> 45897936
C48: .4. | D48: Ticari Mallar | E48: 153 | G48: =IFERROR(VLOOKUP(E48,'30.06.2024 Ana Hs.Mizanı S'!A:G,7,0),0) -> 1.2869428e+08 | K48: .1. | L48: Gelecek Aylara Ait Gelirler | M48: 380 | O48: =-IFERROR(VLOOKUP(M48,'30.06.2024 Ana Hs.Mizanı S'!A:G,7,0),0) -> 20400809
...

Sheet 30.06.2024 Gelir Tablosu S
A4: GELİR TABLOSU (TL)
L6: 45473
A7: A. | C7: Brüt Satışlar | L7: =SUM(L8:L10) -> 2.7759475e+09
B8: .1. | C8: Yurtiçi Satışlar | D8: 600 | L8: =IFERROR(-VLOOKUP(D8,'30.06.2024 Ana Hs.Mizanı S'!A:G,7,0),)+IFERROR(-VLOOKUP(E8,'30.06.2024 Ana Hs.Mizanı S'!A:G,7,0),0)+IFERROR(-VLOOKUP(F8,'30.06.2024 Ana Hs.Mizanı S'!A:G,7,0),0)+IFERROR(-VLOOKUP(G8,'30.06.2024 Ana Hs.Mizanı S'!A:G,7,0),0)+IFERROR(-VLOOKUP(H8,'30.06.2024 Ana Hs.Mizanı S'!A:G,7,0),0)+IFERROR(-VLOOKUP(I8,'30.06.2024 Ana Hs.Mizanı S'!A:G,7,0),0)+IFERROR(-VLOOKUP(J8,'30.06.2024 Ana Hs.Mizanı S'!A:G,7,0),0) -> 2.1934922e+09
B9: .2. | C9: Yurtdışı Satışlar | D9: 601 | L9: =IFERROR(-VLOOKUP(D9,'30.06.2024 Ana Hs.Mizanı S'!A:G,7,0),)+IFERROR(-VLOOKUP(E9,'30.06.2024 Ana Hs.Mizanı S'!A:G,7,0),0)+IFERROR(-VLOOKUP(F9,'30.06.2024 Ana Hs.Mizanı S'!A:G,7,0),0)+IFERROR(-VLOOKUP(G9,'30.06.2024 Ana Hs.Mizanı S'!A:G,7,0),0)+IFERROR(-VLOOKUP(H9,'30.06.2024 Ana Hs.Mizanı S'!A:G,7,0),0)+IFERROR(-VLOOKUP(I9,'30.06.2024 Ana Hs.Mizanı S'!A:G,7,0),0)+IFERROR(-VLOOKUP(J9,'30.06.2024 Ana Hs.Mizanı S'!A:G,7,0),0) -> 35842965
B10: .3. | C10: Diğer Gelirler | D10: 602 | L10: =IFERROR(-VLOOKUP(D10,'30.06.2024 Ana Hs.Mizanı S'!A:G,7,0),)+IFERROR(-VLOOKUP(E10,'30.06.2024 Ana Hs.Mizanı S'!A:G,7,0),0)+IFERROR(-VLOOKUP(F10,'30.06.2024 Ana Hs.Mizanı S'!A:G,7,0),0)+IFERROR(-VLOOKUP(G10,'30.06.2024 Ana Hs.Mizanı S'!A:G,7,0),0)+IFERROR(-VLOOKUP(H10,'30.06.2024 Ana Hs.Mizanı S'!A:G,7,0),0)+IFERROR(-VLOOKUP(I10,'30.06.2024 Ana Hs.Mizanı S'!A:G,7,0),0)+IFERROR(-VLOOKUP(J10,'30.06.2024 Ana Hs.Mizanı S'!A:G,7,0),0) -> 5.4661239e+08 | BV10: 42308
A12: B. | C12: Satış İndirimleri (-) | L12: =SUM(L13:L16) -> -2825910
B13: .1. | C13: Satış İadeleri (-) | D13: 610 | L13: =IFERROR(-VLOOKUP(D13,'30.06.2024 Ana Hs.Mizanı S'!A:G,7,0),)+IFERROR(-VLOOKUP(E13,'30.06.2024 Ana Hs.Mizanı S'!A:G,7,0),0)+IFERROR(-VLOOKUP(F13,'30.06.2024 Ana Hs.Mizanı S'!A:G,7,0),0)+IFERROR(-VLOOKUP(G13,'30.06.2024 Ana Hs.Mizanı S'!A:G,7,0),0)+IFERROR(-VLOOKUP(H13,'30.06.2024 Ana Hs.Mizanı S'!A:G,7,0),0)+IFERROR(-VLOOKUP(I13,'30.06.2024 Ana Hs.Mizanı S'!A:G,7,0),0)+IFERROR(-VLOOKUP(J13,'30.06.2024 Ana Hs.Mizanı S'!A:G,7,0),0) -> -2268217.1
B14: .2. | C14: Satış İskontoları (-) | D14: 611 | L14: =IFERROR(-VLOOKUP(D14,'30.06.2024 Ana Hs.Mizanı S'!A:G,7,0),)+IFERROR(-VLOOKUP(E14,'30.06.2024 Ana Hs.Mizanı S'!A:G,7,0),0)+IFERROR(-VLOOKUP(F14,'30.06.2024 Ana Hs.Mizanı S'!A:G,7,0),0)+IFERROR(-VLOOKUP(G14,'30.06.2024 Ana Hs.Mizanı S'!A:G,7,0),0)+IFERROR(-VLOOKUP(H14,'30.06.2024 Ana Hs.Mizanı S'!A:G,7,0),0)+IFERROR(-VLOOKUP(I14,'30.06.2024 Ana Hs.Mizanı S'!A:G,7,0),0)+IFERROR(-VLOOKUP(J14,'30.06.2024 Ana Hs.Mizanı S'!A:G,7,0),0) -> 0
B15: .3. | C15: Diğer İndirimler (-) | D15: 612 | L15: =IFERROR(-VLOOKUP(D15,'30.06.2024 Ana Hs.Mizanı S'!A:G,7,0),)+IFERROR(-VLOOKUP(E15,'30.06.2024 Ana Hs.Mizanı S'!A:G,7,0),0)+IFERROR(-VLOOKUP(F15,'30.06.2024 Ana Hs.Mizanı S'!A:G,7,0),0)+IFERROR(-VLOOKUP(G15,'30.06.2024 Ana Hs.Mizanı S'!A:G,7,0),0)+IFERROR(-VLOOKUP(H15,'30.06.2024 Ana Hs.Mizanı S'!A:G,7,0),0)+IFERROR(-VLOOKUP(I15,'30.06.2024 Ana Hs.Mizanı S'!A:G,7,0),0)+IFERROR(-VLOOKUP(J15,'30.06.2024 Ana Hs.Mizanı S'!A:G,7,0),0) -> -557692.89
A17: C. | C17: Net Satışlar | L17: =+L12+L7 -> 2.7731216e+09
A19: D. | C19: Satışların Maliyeti (-) | L19: =SUM(L20:L23) -> -1.216152e+09
B20: .1. | C20: Satılan Mamül Maliyeti (-) | D20: 620 | E20: 720 | F20: 730 | G20: 710 | H20: 711 | I20: 721 | J20: 731 | L20: =IFERROR(-VLOOKUP(D20,'30.06.2024 Ana Hs.Mizanı S'!A:G,7,0),)+IFERROR(-VLOOKUP(E20,'30.06.2024 Ana Hs.Mizanı S'!A:G,7,0),0)+IFERROR(-VLOOKUP(F20,'30.06.2024 Ana Hs.Mizanı S'!A:G,7,0),0)+IFERROR(-VLOOKUP(G20,'30.06.2024 Ana Hs.Mizanı S'!A:G,7,0),0)+IFERROR(-VLOOKUP(H20,'30.06.2024 Ana Hs.Mizanı S'!A:G,7,0),0)+IFERROR(-VLOOKUP(I20,'30.06.2024 Ana Hs.Mizanı S'!A:G,7,0),0)+IFERROR(-VLOOKUP(J20,'30.06.2024 Ana Hs.Mizanı S'!A:G,7,0),0) -> -6.9741555e+08
B21: .2. | C21: Satılan Ticari Mallar Maliyeti (-) | D21: 621 | L21: =IFERROR(-VLOOKUP(D21,'30.06.2024 Ana Hs.Mizanı S'!A:G,7,0),)+IFERROR(-VLOOKUP(E21,'30.06.2024 Ana Hs.Mizanı S'!A:G,7,0),0)+IFERROR(-VLOOKUP(F21,'30.06.2024 Ana Hs.Mizanı S'!A:G,7,0),0)+IFERROR(-VLOOKUP(G21,'30.06.2024 Ana Hs.Mizanı S'!A:G,7,0),0)+IFERROR(-VLOOKUP(H21,'30.06.2024 Ana Hs.Mizanı S'!A:G,7,0),0)+IFERROR(-VLOOKUP(I21,'30.06.2024 Ana Hs.Mizanı S'!A:G,7,0),0)+IFERROR(-VLOOKUP(J21,'30.06.2024 Ana Hs.Mizanı S'!A:G,7,0),0) -> -3.5400307e+08
B22: .3. | C22: Satılan Hizmet Maliyeti (-) | D22: 622 | E22: 740 | L22: =IFERROR(-VLOOKUP(D22,'30.06.2024 Ana Hs.Mizanı S'!A:G,7,0),)+IFERROR(-VLOOKUP(E22,'30.06.2024 Ana Hs.Mizanı S'!A:G,7,0),0)+IFERROR(-VLOOKUP(F22,'30.06.2024 Ana Hs.Mizanı S'!A:G,7,0),0)+IFERROR(-VLOOKUP(G22,'30.06.2024 Ana Hs.Mizanı S'!A:G,7,0),0)+IFERROR(-VLOOKUP(H22,'30.06.2024 Ana Hs.Mizanı S'!A:G,7,0),0)+IFERROR(-VLOOKUP(I22,'30.06.2024 Ana Hs.Mizanı S'!A:G,7,0),0)+IFERROR(-VLOOKUP(J22,'30.06.2024 Ana Hs.Mizanı S'!A:G,7,0),0) -> -1.6473334e+08
B23: .4. | C23: Diğer Satışların Maliyeti (-) | D23: 623 | L23: =IFERROR(-VLOOKUP(D23,'30.06.2024 Ana Hs.Mizanı S'!A:G,7,0),)+IFERROR(-VLOOKUP(E23,'30.06.2024 Ana Hs.Mizanı S'!A:G,7,0),0)+IFERROR(-VLOOKUP(F23,'30.06.2024 Ana Hs.Mizanı S'!A:G,7,0),0)+IFERROR(-VLOOKUP(G23,'30.06.2024 Ana Hs.Mizanı S'!A:G,7,0),0)+IFERROR(-VLOOKUP(H23,'30.06.2024 Ana Hs.Mizanı S'!A:G,7,0),0)+IFERROR(-VLOOKUP(I23,'30.06.2024 Ana Hs.Mizanı S'!A:G,7,0),0)+IFERROR(-VLOOKUP(J23,'30.06.2024 Ana Hs.Mizanı S'!A:G,7,0),0) -> 0
C24: Brüt Satış Karı veya Zararı | L24: =+L17+L19 -> 1.5569697e+09
A26: E. | C26: Faaliyet Giderleri (-) | L26: =SUM(L27:L29) -> -1.0074301e+09
B27: .1. | C27: Araştırma ve Geliştirme Giderleri (-) | D27: 750 | L27: =IFERROR(-VLOOKUP(D27,'30.06.2024 Ana Hs.Mizanı S'!A:G,7,0),)+IFERROR(-VLOOKUP(E27,'30.06.2024 Ana Hs.Mizanı S'!A:G,7,0),0)+IFERROR(-VLOOKUP(F27,'30.06.2024 Ana Hs.Mizanı S'!A:G,7,0),0)+IFERROR(-VLOOKUP(G27,'30.06.2024 Ana Hs.Mizanı S'!A:G,7,0),0)+IFERROR(-VLOOKUP(H27,'30.06.2024 Ana Hs.Mizanı S'!A:G,7,0),0)+IFERROR(-VLOOKUP(I27,'30.06.2024 Ana Hs.Mizanı S'!A:G,7,0),0)+IFERROR(-VLOOKUP(J27,'30.06.2024 Ana Hs.Mizanı S'!A:G,7,0),0) -> 0
B28: .2. | C28: Pazarlama, Satış ve Dağıtım Giderleri (-) | D28: 631 | E28: 760 | F28: 761 | L28: =IFERROR(-VLOOKUP(D28,'30.06.2024 Ana Hs.Mizanı S'!A:G,7,0),)+IFERROR(-VLOOKUP(E28,'30.06.2024 Ana Hs.Mizanı S'!A:G,7,0),0)+IFERROR(-VLOOKUP(F28,'30.06.2024 Ana Hs.Mizanı S'!A:G,7,0),0)+IFERROR(-VLOOKUP(G28,'30.06.2024 Ana Hs.Mizanı S'!A:G,7,0),0)+IFERROR(-VLOOKUP(H28,'30.06.2024 Ana Hs.Mizanı S'!A:G,7,0),0)+IFERROR(-VLOOKUP(I28,'30.06.2024 Ana Hs.Mizanı S'!A:G,7,0),0)+IFERROR(-VLOOKUP(J28,'30.06.2024 Ana Hs.Mizanı S'!A:G,7,0),0) -> -9.0045295e+08
B29: .3. | C29: Genel Yönetim Giderleri (-) | D29: 770 | E29: 632 | F29: 771 | L29: =IFERROR(-VLOOKUP(D29,'30.06.2024 Ana Hs.Mizanı S'!A:G,7,0),)+IFERROR(-VLOOKUP(E29,'30.06.2024 Ana Hs.Mizanı S'!A:G,7,0),0)+IFERROR(-VLOOKUP(F29,'30.06.2024 Ana Hs.Mizanı S'!A:G,7,0),0)+IFERROR(-VLOOKUP(G29,'30.06.2024 Ana Hs.Mizanı S'!A:G,7,0),0)+IFERROR(-VLOOKUP(H29,'30.06.2024 Ana Hs.Mizanı S'!A:G,7,0),0)+IFERROR(-VLOOKUP(I29,'30.06.2024 Ana Hs.Mizanı S'!A:G,7,0),0)+IFERROR(-VLOOKUP(J29,'30.06.2024 Ana Hs.Mizanı S'!A:G,7,0),0) -> -1.0697716e+08
C31: Faaliyet Karı veya Zararı | L31: =+L24+L26 -> 5.4953957e+08
A33: F. | C33: Diğer Faaliyetlerden Olağan Gelir ve Karlar | L33: =SUM(L34:L39) -> 48179272
B34: .1. | C34: Faiz Gelirleri | D34: 642 | L34: =IFERROR(-VLOOKUP(D34,'30.06.2024 Ana Hs.Mizanı S'!A:G,7,0),)+IFERROR(-VLOOKUP(E34,'30.06.2024 Ana Hs.Mizanı S'!A:G,7,0),0)+IFERROR(-VLOOKUP(F34,'30.06.2024 Ana Hs.Mizanı S'!A:G,7,0),0)+IFERROR(-VLOOKUP(G34,'30.06.2024 Ana Hs.Mizanı S'!A:G,7,0),0)+IFERROR(-VLOOKUP(H34,'30.06.2024 Ana Hs.Mizanı S'!A:G,7,0),0)+IFERROR(-VLOOKUP(I34,'30.06.2024 Ana Hs.Mizanı S'!A:G,7,0),0)+IFERROR(-VLOOKUP(J34,'30.06.2024 Ana Hs.Mizanı S'!A:G,7,0),0) -> 36812606
B35: .2. | C35: Konusu Kalmayan Karşılıklar | D35: 644 | L35: =IFERROR(-VLOOKUP(D35,'30.06.2024 Ana Hs.Mizanı S'!A:G,7,0),)+IFERROR(-VLOOKUP(E35,'30.06.2024 Ana Hs.Mizanı S'!A:G,7,0),0)+IFERROR(-VLOOKUP(F35,'30.06.2024 Ana Hs.Mizanı S'!A:G,7,0),0)+IFERROR(-VLOOKUP(G35,'30.06.2024 Ana Hs.Mizanı S'!A:G,7,0),0)+IFERROR(-VLOOKUP(H35,'30.06.2024 Ana Hs.Mizanı S'!A:G,7,0),0)+IFERROR(-VLOOKUP(I35,'30.06.2024 Ana Hs.Mizanı S'!A:G,7,0),0)+IFERROR(-VLOOKUP(J35,'30.06.2024 Ana Hs.Mizanı S'!A:G,7,0),0) -> 0
B36: .3. | C36: Menkul Kıymet Satış Karları | D36: 645 | L36: =IFERROR(-VLOOKUP(D36,'30.06.2024 Ana Hs.Mizanı S'!A:G,7,0),)+IFERROR(-VLOOKUP(E36,'30.06.2024 Ana Hs.Mizanı S'!A:G,7,0),0)+IFERROR(-VLOOKUP(F36,'30.06.2024 Ana Hs.Mizanı S'!A:G,7,0),0)+IFERROR(-VLOOKUP(G36,'30.06.2024 Ana Hs.Mizanı S'!A:G,7,0),0)+IFERROR(-VLOOKUP(H36,'30.06.2024 Ana Hs.Mizanı S'!A:G,7,0),0)+IFERROR(-VLOOKUP(I36,'30.06.2024 Ana Hs.Mizanı S'!A:G,7,0),0)+IFERROR(-VLOOKUP(J36,'30.06.2024 Ana Hs.Mizanı S'!A:G,7,0),0) -> 0
B37: .4. | C37: Kambiyo Karları | D37: 646 | L37: =IFERROR(-VLOOKUP(D37,'30.06.2024 Ana Hs.Mizanı S'!A:G,7,0),)+IFERROR(-VLOOKUP(E37,'30.06.2024 Ana Hs.Mizanı S'!A:G,7,0),0)+IFERROR(-VLOOKUP(F37,'30.06.2024 Ana Hs.Mizanı S'!A:G,7,0),0)+IFERROR(-VLOOKUP(G37,'30.06.2024 Ana Hs.Mizanı S'!A:G,7,0),0)+IFERROR(-VLOOKUP(H37,'30.06.2024 Ana Hs.Mizanı S'!A:G,7,0),0)+IFERROR(-VLOOKUP(I37,'30.06.2024 Ana Hs.Mizanı S'!A:G,7,0),0)+IFERROR(-VLOOKUP(J37,'30.06.2024 Ana Hs.Mizanı S'!A:G,7,0),0) -> 9514813.4
B38: .5. | C38: Diğer Olağan Gelir ve Karlar | D38: 649 | L38: =IFERROR(-VLOOKUP(D38,'30.06.2024 Ana Hs.Mizanı S'!A:G,7,0),)+IFERROR(-VLOOKUP(E38,'30.06.2024 Ana Hs.Mizanı S'!A:G,7,0),0)+IFERROR(-VLOOKUP(F38,'30.06.2024 Ana Hs.Mizanı S'!A:G,7,0),0)+IFERROR(-VLOOKUP(G38,'30.06.2024 Ana Hs.Mizanı S'!A:G,7,0),0)+IFERROR(-VLOOKUP(H38,'30.06.2024 Ana Hs.Mizanı S'!A:G,7,0),0)+IFERROR(-VLOOKUP(I38,'30.06.2024 Ana Hs.Mizanı S'!A:G,7,0),0)+IFERROR(-VLOOKUP(J38,'30.06.2024 Ana Hs.Mizanı S'!A:G,7,0),0) -> 1851851.8
A40: G. | C40: Diğer Faaliyetlerden Olağan Gider ve Zararlar (-) | L40: =SUM(L41:L46) -> -73039310
B41: .1. | C41: Komisyon Giderleri (-) | D41: 653 | L41: =IFERROR(-VLOOKUP(D41,'30.06.2024 Ana Hs.Mizanı S'!A:G,7,0),)+IFERROR(-VLOOKUP(E41,'30.06.2024 Ana Hs.Mizanı S'!A:G,7,0),0)+IFERROR(-VLOOKUP(F41,'30.06.2024 Ana Hs.Mizanı S'!A:G,7,0),0)+IFERROR(-VLOOKUP(G41,'30.06.2024 Ana Hs.Mizanı S'!A:G,7,0),0)+IFERROR(-VLOOKUP(H41,'30.06.2024 Ana Hs.Mizanı S'!A:G,7,0),0)+IFERROR(-VLOOKUP(I41,'30.06.2024 Ana Hs.Mizanı S'!A:G,7,0),0)+IFERROR(-VLOOKUP(J41,'30.06.2024 Ana Hs.Mizanı S'!A:G,7,0),0) -> 0
B42: .2. | C42: Karşılık Giderleri (-) | D42: 654 | L42: =IFERROR(-VLOOKUP(D42,'30.06.2024 Ana Hs.Mizanı S'!A:G,7,0),)+IFERROR(-VLOOKUP(E42,'30.06.2024 Ana Hs.Mizanı S'!A:G,7,0),0)+IFERROR(-VLOOKUP(F42,'30.06.2024 Ana Hs.Mizanı S'!A:G,7,0),0)+IFERROR(-VLOOKUP(G42,'30.06.2024 Ana Hs.Mizanı S'!A:G,7,0),0)+IFERROR(-VLOOKUP(H42,'30.06.2024 Ana Hs.Mizanı S'!A:G,7,0),0)+IFERROR(-VLOOKUP(I42,'30.06.2024 Ana Hs.Mizanı S'!A:G,7,0),0)+IFERROR(-VLOOKUP(J42,'30.06.2024 Ana Hs.Mizanı S'!A:G,7,0),0) -> 0
B43: .3. | C43: Menkul Kıymet Satış Zararları (-) | D43: 655 | L43: =IFERROR(-VLOOKUP(D43,'30.06.2024 Ana Hs.Mizanı S'!A:G,7,0),)+IFERROR(-VLOOKUP(E43,'30.06.2024 Ana Hs.Mizanı S'!A:G,7,0),0)+IFERROR(-VLOOKUP(F43,'30.06.2024 Ana Hs.Mizanı S'!A:G,7,0),0)+IFERROR(-VLOOKUP(G43,'30.06.2024 Ana Hs.Mizanı S'!A:G,7,0),0)+IFERROR(-VLOOKUP(H43,'30.06.2024 Ana Hs.Mizanı S'!A:G,7,0),0)+IFERROR(-VLOOKUP(I43,'30.06.2024 Ana Hs.Mizanı S'!A:G,7,0),0)+IFERROR(-VLOOKUP(J43,'30.06.2024 Ana Hs.Mizanı S'!A:G,7,0),0) -> 0
B44: .4. | C44: Kambiyo Zararları (-) | D44: 656 | L44: =IFERROR(-VLOOKUP(D44,'30.06.2024 Ana Hs.Mizanı S'!A:G,7,0),)+IFERROR(-VLOOKUP(E44,'30.06.2024 Ana Hs.Mizanı S'!A:G,7,0),0)+IFERROR(-VLOOKUP(F44,'30.06.2024 Ana Hs.Mizanı S'!A:G,7,0),0)+IFERROR(-VLOOKUP(G44,'30.06.2024 Ana Hs.Mizanı S'!A:G,7,0),0)+IFERROR(-VLOOKUP(H44,'30.06.2024 Ana Hs.Mizanı S'!A:G,7,0),0)+IFERROR(-VLOOKUP(I44,'30.06.2024 Ana Hs.Mizanı S'!A:G,7,0),0)+IFERROR(-VLOOKUP(J44,'30.06.2024 Ana Hs.Mizanı S'!A:G,7,0),0) -> -4590248.1
B45: .5. | C45: Diğer Olağan Gider ve Zararlar (-) | E45: 659 | L45: =IFERROR(-VLOOKUP(D45,'30.06.2024 Ana Hs.Mizanı S'!A:G,7,0),)+IFERROR(-VLOOKUP(E45,'30.06.2024 Ana Hs.Mizanı S'!A:G,7,0),0)+IFERROR(-VLOOKUP(F45,'30.06.2024 Ana Hs.Mizanı S'!A:G,7,0),0)+IFERROR(-VLOOKUP(G45,'30.06.2024 Ana Hs.Mizanı S'!A:G,7,0),0)+IFERROR(-VLOOKUP(H45,'30.06.2024 Ana Hs.Mizanı S'!A:G,7,0),0)+IFERROR(-VLOOKUP(I45,'30.06.2024 Ana Hs.Mizanı S'!A:G,7,0),0)+IFERROR(-VLOOKUP(J45,'30.06.2024 Ana Hs.Mizanı S'!A:G,7,0),0) -> 0
B46: .6. | C46: Enflasyon Düzeltmesi Zaraları | D46: 658 | L46: =-IFERROR(VLOOKUP(D46,'30.06.2024 Ana Hs.Mizanı S'!A:G,7,0),0) -> -68449062
A47: H. | C47: Finansman Giderleri (-) | L47: =SUM(L48:L50) -> -88304386
B48: .1. | C48: Kısa Vadeli Borçlanma Giderleri (-) | D48: 780 | E48: 660 | L48: =IFERROR(-VLOOKUP(D48,'30.06.2024 Ana Hs.Mizanı S'!A:G,7,0),)+IFERROR(-VLOOKUP(E48,'30.06.2024 Ana Hs.Mizanı S'!A:G,7,0),0)+IFERROR(-VLOOKUP(F48,'30.06.2024 Ana Hs.Mizanı S'!A:G,7,0),0)+IFERROR(-VLOOKUP(G48,'30.06.2024 Ana Hs.Mizanı S'!A:G,7,0),0)+IFERROR(-VLOOKUP(H48,'30.06.2024 Ana Hs.Mizanı S'!A:G,7,0),0)+IFERROR(-VLOOKUP(I48,'30.06.2024 Ana Hs.Mizanı S'!A:G,7,0),0)+IFERROR(-VLOOKUP(J48,'30.06.2024 Ana Hs.Mizanı S'!A:G,7,0),0) -> -88304386
B49: .2. | C49: Uzun Vadeli Borçlanma Giderleri (-) | D49: 661 | L49: =IFERROR(-VLOOKUP(D49,'30.06.2024 Ana Hs.Mizanı S'!A:G,7,0),)+IFERROR(-VLOOKUP(E49,'30.06.2024 Ana Hs.Mizanı S'!A:G,7,0),0)+IFERROR(-VLOOKUP(F49,'30.06.2024 Ana Hs.Mizanı S'!A:G,7,0),0)+IFERROR(-VLOOKUP(G49,'30.06.2024 Ana Hs.Mizanı S'!A:G,7,0),0)+IFERROR(-VLOOKUP(H49,'30.06.2024 Ana Hs.Mizanı S'!A:G,7,0),0)+IFERROR(-VLOOKUP(I49,'30.06.2024 Ana Hs.Mizanı S'!A:G,7,0),0)+IFERROR(-VLOOKUP(J49,'30.06.2024 Ana Hs.Mizanı S'!A:G,7,0),0) -> 0
C51: Olağan Kar veya Zarar | L51: =+L47+L40+L33+L31 -> 4.3637514e+08
A53: I. | C53: Olağan Dışı Gelir ve Karlar | L53: =SUM(L54:L56) -> 23629517
...

Sheet Sayfa1

Sheet 30.06.2024 Ana Hs.Mizanı S
A1: Hesap Kodu | B1: Hesap Adı | C1: Borç | D1: Alacak | E1: Bakiye Borç | F1: Bakiye Alacak | G1: Bakiye
A2: 100 | B2: KASA HESABI | C2: 73628799 | D2: 73136382 | E2: 492417 | F2: 0 | G2: 492417
A3: 101 | B3: ALINAN ÇEKLER | C3: 7.2233371e+08 | D3: 6.2114882e+08 | E3: 1.0118489e+08 | F3: 0 | G3: 1.0118489e+08
A4: 102 | B4: BANKALAR | C4: 1.6800293e+10 | D4: 1.6430045e+10 | E4: 3.7024815e+08 | F4: 0 | G4: 3.7024815e+08
A5: 103 | B5: VERİLEN ÇEKLER VE ÖDEME EMİRLERİ (-) | C5: 5.1735651e+08 | D5: 5.1735651e+08 | E5: 0 | F5: 0 | G5: 0
A6: 108 | B6: DİĞER HAZIR DEĞERLER | C6: 9.3324288e+08 | D6: 9.2974483e+08 | E6: 3498049.2 | F6: 0 | G6: 3498049.2
A7: 111 | B7: ÖZEL KESİM TAHVİL, SENET VE BONOLARI | C7: 1.4106989e+08 | D7: 69819278 | E7: 71250609 | F7: 0 | G7: 71250609
A8: 118 | B8: DİĞER MENKUL KIYMETLER | C8: 3.3791736e+08 | D8: 2.7983497e+08 | E8: 58082389 | F8: 0 | G8: 58082389
A9: 120 | B9: ALICILAR | C9: 3.9785106e+09 | D9: 3.6710078e+09 | E9: 3.0750284e+08 | F9: 0 | G9: 3.0750284e+08
A10: 126 | B10: VERİLEN DEPOZİTO VE TEMİNATLAR | C10: 1.2354676e+08 | D10: 85011032 | E10: 38535728 | F10: 0 | G10: 38535728
A11: 127 | B11: DİĞER TİCARİ ALACAKLAR | C11: 3578938.2 | D11: 0 | E11: 3578938.2 | F11: 0 | G11: 3578938.2
A12: 135 | B12: PERSONELDEN ALACAKLAR | C12: 28183629 | D12: 18112974 | E12: 10070654 | F12: 0 | G12: 10070654
A13: 136 | B13: DİĞER ÇEŞİTLİ ALACAKLAR | C13: 3.0532656e+08 | D13: 3.000634e+08 | E13: 5263164 | F13: 0 | G13: 5263164
... A100: 780 | B100: FİNANSMAN GİDERLERİ | C100: 69110681 | D100: 8378840.7 | E100: 60731840 | F100: 0 | G100: 60731840

Sheet 30.06.2024 Detay Mizan  S
A1: UZUNLUK | B1: Hesap Kodu | C1: Hesap Adı | D1: Borç | E1: Alacak | F1: Bakiye Borç | G1: Bakiye Alacak | H1: Bakiye
A2: =+LEN(B2) -> 3 | B2: 100 | C2: KASA HESABI | D2: 73628799 | E2: 73136382 | F2: 492417 | G2: 0 | H2: 492417
A3: =+LEN(B3) -> 7 | B3: 100.005 | C3: TD MERKEZ KASALAR | D3: 32258.13 | E3: 32258.13 | F3: 0 | G3: 0 | H3: 0
A4: =+LEN(B4) -> 11 | B4: 100.005.005 | C4: TD MERKEZ OFİS KASA TL | D4: 32258.13 | E4: 32258.13 | F4: 0 | G4: 0 | H4: 0
A5: =+LEN(B5) -> 7 | B5: 100.050 | C5: ŞUBE KASALARI | D5: 73596541 | E5: 73104124 | F5: 492417 | G5: 0 | H5: 492417
A6: =+LEN(B6) -> 11 | B6: 100.050.010 | C6: VİALAND ŞUBE KASASI | D6: 4604020 | E6: 4590340 | F6: 13679.96 | G6: 0 | H6: 13679.96
A7: =+LEN(B7) -> 11 | B7: 100.050.020 | C7: MAVİBAHÇE ŞUBE KASASI | D7: 678771.65 | E7: 663810 | F7: 14961.65 | G7: 0 | H7: 14961.65
A8: =+LEN(B8) -> 11 | B8: 100.050.045 | C8: ŞUBE 212 KASA | D8: 1477468.6 | E8: 1459220 | F8: 18248.64 | G8: 0 | H8: 18248.64
A9: =+LEN(B9) -> 11 | B9: 100.050.055 | C9: ŞUBE BURSA KORUPARK KASASI | D9: 4915032.7 | E9: 4898100 | F9: 16932.68 | G9: 0 | H9: 16932.68
A10: =+LEN(B10) -> 11 | B10: 100.050.070 | C10: ŞUBE ANKARA OPTİMUM KASA | D10: 1421407.7 | E10: 1393340 | F10: 28067.69 | G10: 0 | H10: 28067.69
A11: =+LEN(B11) -> 11 | B11: 100.050.080 | C11: ŞUBE TRUMP TOWERS KASA | D11: 1059631.8 | E11: 1023715 | F11: 35916.8 | G11: 0 | H11: 35916.8
A12: =+LEN(B12) -> 11 | B12: 100.050.085 | C12: ŞUBE ANTALYA TERRACİTY KASA | D12: 2868022.5 | E12: 2837770 | F12: 30252.55 | G12: 0 | H12: 30252.55
A13: =+LEN(B13) -> 11 | B13: 100.050.095 | C13: ŞUBE OLİVİUM KASA | D13: 1923036.4 | E13: 1921540 | F13: 1496.35 | G13: 0 | H13: 1496.35
... A1952: =+LEN(B1952) -> 11 | B1952: 780.021.021 | C1952: BURGANBANK ROTATİF KREDİ FAİZ GİDERLERİ | D1952: 2441312.5 | E1952: 0 | F1952: 2441312.5 | G1952: 0 | H1952: 2441312.5

Sheet Sayfa2
